INFO 2020-10-14 13:25:44,482 basehttp 124 [32m[32m"GET / HTTP/1.1" 200 7152[0m[0m
INFO 2020-10-14 13:25:44,966 basehttp 124 [32m[32m"GET /favicon.ico HTTP/1.1" 302 0[0m[0m
INFO 2020-10-14 13:26:30,458 basehttp 124 [32m[32m"POST /authorization/ HTTP/1.1" 200 260[0m[0m
INFO 2020-10-14 13:26:30,528 basehttp 124 [32m[32m"GET /user/home/ HTTP/1.1" 200 43508[0m[0m
INFO 2020-10-14 13:26:30,962 basehttp 124 [32m[32m"GET /test/car_platform/ HTTP/1.1" 200 294[0m[0m
INFO 2020-10-14 13:26:31,034 basehttp 124 [32m[32m"POST /user/home/ HTTP/1.1" 200 106[0m[0m
INFO 2020-10-14 13:26:31,118 basehttp 124 [32m[32m"GET /user/user/22/ HTTP/1.1" 200 21529[0m[0m
INFO 2020-10-14 13:26:31,284 basehttp 124 [32m[32m"GET /user/file/22/?page=1&limit=30 HTTP/1.1" 200 48[0m[0m
INFO 2020-10-14 13:26:52,467 basehttp 124 [32m[32m"GET /calculate/parse/ HTTP/1.1" 200 54135[0m[0m
INFO 2020-10-14 13:26:52,936 basehttp 124 [32m[32m"GET /test/car_platform/ HTTP/1.1" 200 294[0m[0m
INFO 2020-10-14 13:26:53,026 basehttp 124 [32m[32m"PUT /calculate/channellist/ HTTP/1.1" 200 66[0m[0m
INFO 2020-10-14 13:26:53,064 basehttp 124 [32m[32m"GET /user/user/22/ HTTP/1.1" 200 21529[0m[0m
INFO 2020-10-14 13:26:53,269 basehttp 124 [32m[32m"GET /calculate/parse/ HTTP/1.1" 200 54135[0m[0m
INFO 2020-10-14 13:26:53,567 basehttp 124 [32m[32m"GET /test/car_platform/ HTTP/1.1" 200 294[0m[0m
INFO 2020-10-14 13:26:53,652 basehttp 124 [32m[32m"PUT /calculate/channellist/ HTTP/1.1" 200 66[0m[0m
INFO 2020-10-14 13:26:53,682 basehttp 124 [32m[32m"GET /user/user/22/ HTTP/1.1" 200 21529[0m[0m
INFO 2020-10-14 13:31:59,434 basehttp 124 [32m[32m"GET /time/submit/ HTTP/1.1" 200 39663[0m[0m
INFO 2020-10-14 13:31:59,815 basehttp 124 [32m[32m"GET /test/car_platform/ HTTP/1.1" 200 294[0m[0m
INFO 2020-10-14 13:32:00,129 basehttp 124 [32m[32m"GET /user/user/22/ HTTP/1.1" 200 21529[0m[0m
INFO 2020-10-14 13:32:00,234 basehttp 124 [32m[32m"GET /time/item/?user_id=22 HTTP/1.1" 200 2418[0m[0m
INFO 2020-10-14 13:32:00,467 basehttp 124 [32m[32m"GET /time/task/?user_id=22 HTTP/1.1" 200 16043[0m[0m
INFO 2020-10-14 13:32:05,831 basehttp 124 [32m[32m"GET /time/submit/ HTTP/1.1" 200 39663[0m[0m
INFO 2020-10-14 13:32:06,099 basehttp 124 [32m[32m"GET /test/car_platform/ HTTP/1.1" 200 294[0m[0m
INFO 2020-10-14 13:32:06,384 basehttp 124 [32m[32m"GET /user/user/22/ HTTP/1.1" 200 21529[0m[0m
INFO 2020-10-14 13:32:06,479 basehttp 124 [32m[32m"GET /time/item/?user_id=22 HTTP/1.1" 200 2418[0m[0m
INFO 2020-10-14 13:32:06,731 basehttp 124 [32m[32m"GET /time/task/?user_id=22 HTTP/1.1" 200 16043[0m[0m
INFO 2020-10-14 13:32:07,754 basehttp 124 [32m[32m"GET /bug/page/ HTTP/1.1" 200 18782[0m[0m
INFO 2020-10-14 13:32:08,075 basehttp 124 [32m[32m"GET /test/car_platform/ HTTP/1.1" 200 294[0m[0m
INFO 2020-10-14 13:32:08,123 basehttp 124 [32m[32m"GET /user/user/22/ HTTP/1.1" 200 21529[0m[0m
INFO 2020-10-14 13:32:08,294 basehttp 124 [32m[32m"GET /bug/info/?page=1&limit=20 HTTP/1.1" 200 570[0m[0m
INFO 2020-10-14 13:32:09,087 basehttp 124 [32m[32m"GET /script/info/ HTTP/1.1" 200 16163[0m[0m
INFO 2020-10-14 13:32:09,360 basehttp 124 [32m[32m"GET /test/car_platform/ HTTP/1.1" 200 294[0m[0m
INFO 2020-10-14 13:32:09,430 basehttp 124 [32m[32m"GET /user/user/22/ HTTP/1.1" 200 21529[0m[0m
INFO 2020-10-14 15:59:10,464 basehttp 124 [32m[32m"GET / HTTP/1.1" 200 7152[0m[0m
INFO 2020-10-14 15:59:13,305 basehttp 124 [32m[32m"POST /authorization/ HTTP/1.1" 200 260[0m[0m
INFO 2020-10-14 15:59:13,367 basehttp 124 [32m[32m"GET /user/home/ HTTP/1.1" 200 43508[0m[0m
INFO 2020-10-14 15:59:13,763 basehttp 124 [32m[32m"GET /test/car_platform/ HTTP/1.1" 200 294[0m[0m
INFO 2020-10-14 15:59:13,826 basehttp 124 [32m[32m"POST /user/home/ HTTP/1.1" 200 106[0m[0m
INFO 2020-10-14 15:59:13,888 basehttp 124 [32m[32m"GET /user/user/22/ HTTP/1.1" 200 21529[0m[0m
INFO 2020-10-14 15:59:14,057 basehttp 124 [32m[32m"GET /user/file/22/?page=1&limit=30 HTTP/1.1" 200 48[0m[0m
INFO 2020-10-14 15:59:15,051 basehttp 124 [32m[32m"GET /time/submit/ HTTP/1.1" 200 39663[0m[0m
INFO 2020-10-14 15:59:15,372 basehttp 124 [32m[32m"GET /test/car_platform/ HTTP/1.1" 200 294[0m[0m
INFO 2020-10-14 15:59:15,506 basehttp 124 [32m[32m"GET /time/task/?user_id=22 HTTP/1.1" 200 88[0m[0m
INFO 2020-10-14 15:59:15,617 basehttp 124 [32m[32m"GET /user/user/22/ HTTP/1.1" 200 21529[0m[0m
INFO 2020-10-14 15:59:15,755 basehttp 124 [32m[32m"GET /time/item/?user_id=22 HTTP/1.1" 200 2494[0m[0m
INFO 2020-10-14 16:09:38,152 basehttp 124 [32m[32m"GET /time/submit/ HTTP/1.1" 200 39663[0m[0m
INFO 2020-10-14 16:09:38,560 basehttp 124 [32m[32m"GET /test/car_platform/ HTTP/1.1" 200 294[0m[0m
INFO 2020-10-14 16:09:38,753 basehttp 124 [32m[32m"GET /time/task/?user_id=22 HTTP/1.1" 200 88[0m[0m
INFO 2020-10-14 16:09:38,868 basehttp 124 [32m[32m"GET /user/user/22/ HTTP/1.1" 200 21529[0m[0m
INFO 2020-10-14 16:09:38,924 basehttp 124 [32m[32m"GET /time/item/?user_id=22 HTTP/1.1" 200 2494[0m[0m
INFO 2020-10-14 16:09:39,019 basehttp 124 [32m[32m"GET /favicon.ico HTTP/1.1" 302 0[0m[0m
INFO 2020-10-14 16:09:39,026 basehttp 124 [32m[32m"GET /static/image/favicon.ico HTTP/1.1" 200 67646[0m[0m
INFO 2020-10-15 10:57:02,251 basehttp 124 [32m[32m"GET /user/file/1/ HTTP/1.1" 200 48[0m[0m
INFO 2020-10-15 10:57:23,364 basehttp 124 [32m[32m"GET /user/file/4/ HTTP/1.1" 200 48[0m[0m
INFO 2020-10-15 10:57:55,821 basehttp 124 [32m[32m"GET /user/user/1 HTTP/1.1" 301 0[0m[0m
INFO 2020-10-15 10:57:55,936 basehttp 124 [32m[32m"GET /user/user/1/ HTTP/1.1" 200 21526[0m[0m
INFO 2020-10-15 10:58:14,418 basehttp 124 [32m[32m"GET / HTTP/1.1" 200 7152[0m[0m
INFO 2020-10-15 10:58:16,513 basehttp 124 [32m[32m"POST /authorization/ HTTP/1.1" 200 260[0m[0m
INFO 2020-10-15 10:58:16,539 basehttp 124 [32m[32m"GET /user/home/ HTTP/1.1" 200 43508[0m[0m
INFO 2020-10-15 10:58:16,979 basehttp 124 [32m[32m"GET /test/car_platform/ HTTP/1.1" 200 294[0m[0m
INFO 2020-10-15 10:58:17,032 basehttp 124 [32m[32m"POST /user/home/ HTTP/1.1" 200 106[0m[0m
INFO 2020-10-15 10:58:17,116 basehttp 124 [32m[32m"GET /user/user/22/ HTTP/1.1" 200 21529[0m[0m
INFO 2020-10-15 10:58:17,239 basehttp 124 [32m[32m"GET /static/home/lib/admin.js HTTP/1.1" 304 0[0m[0m
INFO 2020-10-15 10:58:17,323 basehttp 124 [32m[32m"GET /user/file/22/?page=1&limit=30 HTTP/1.1" 200 48[0m[0m
INFO 2020-10-15 10:58:19,345 basehttp 124 [32m[32m"GET /user/logout/ HTTP/1.1" 200 7152[0m[0m
INFO 2020-10-15 10:58:21,886 basehttp 124 [32m[32m"POST /authorization/ HTTP/1.1" 200 248[0m[0m
INFO 2020-10-15 10:58:21,909 basehttp 124 [32m[32m"GET /user/home/ HTTP/1.1" 200 43508[0m[0m
INFO 2020-10-15 10:58:22,195 basehttp 124 [32m[32m"GET /test/car_platform/ HTTP/1.1" 200 294[0m[0m
INFO 2020-10-15 10:58:22,239 basehttp 124 [32m[32m"POST /user/home/ HTTP/1.1" 200 106[0m[0m
INFO 2020-10-15 10:58:22,328 basehttp 124 [32m[32m"GET /user/user/4/ HTTP/1.1" 200 21526[0m[0m
INFO 2020-10-15 10:58:22,488 basehttp 124 [32m[32m"GET /user/file/4/?page=1&limit=30 HTTP/1.1" 200 48[0m[0m
INFO 2020-10-15 10:58:29,599 basehttp 124 [32m[32m"GET /user/home/ HTTP/1.1" 200 43508[0m[0m
INFO 2020-10-15 10:58:30,235 basehttp 124 [32m[32m"GET /test/car_platform/ HTTP/1.1" 200 294[0m[0m
INFO 2020-10-15 10:58:30,281 basehttp 124 [32m[32m"POST /user/home/ HTTP/1.1" 200 106[0m[0m
INFO 2020-10-15 10:58:30,402 basehttp 124 [32m[32m"GET /user/user/4/ HTTP/1.1" 200 21526[0m[0m
INFO 2020-10-15 10:58:30,656 basehttp 124 [32m[32m"GET /user/file/4/?page=1&limit=30 HTTP/1.1" 200 48[0m[0m
INFO 2020-10-15 10:58:30,735 basehttp 124 [32m[32m"GET /favicon.ico HTTP/1.1" 302 0[0m[0m
INFO 2020-10-15 10:58:30,751 basehttp 124 [32m[32m"GET /static/image/favicon.ico HTTP/1.1" 200 67646[0m[0m
ERROR 2020-10-15 11:00:23,670 exception 135 [31m[31mInternal Server Error: /user/home/[0m[0m
Traceback (most recent call last):
  File "/home/zheng/.virtualenvs/EPGN/lib/python3.5/site-packages/django/core/handlers/exception.py", line 41, in inner
    response = get_response(request)
  File "/home/zheng/.virtualenvs/EPGN/lib/python3.5/site-packages/django/core/handlers/base.py", line 187, in _get_response
    response = self.process_exception_by_middleware(e, request)
  File "/home/zheng/.virtualenvs/EPGN/lib/python3.5/site-packages/django/core/handlers/base.py", line 185, in _get_response
    response = wrapped_callback(request, *callback_args, **callback_kwargs)
  File "/home/zheng/Documents/WorkFile/EPGN_INFO/apps/users/views.py", line 148, in home
    user = User.objects.get(id=user_id)
  File "/home/zheng/.virtualenvs/EPGN/lib/python3.5/site-packages/django/db/models/manager.py", line 85, in manager_method
    return getattr(self.get_queryset(), name)(*args, **kwargs)
  File "/home/zheng/.virtualenvs/EPGN/lib/python3.5/site-packages/django/db/models/query.py", line 379, in get
    self.model._meta.object_name
users.models.DoesNotExist: User matching query does not exist.
ERROR 2020-10-15 11:00:23,723 basehttp 124 [31m[31m"POST /user/home/ HTTP/1.1" 500 84588[0m[0m
ERROR 2020-10-15 11:00:52,741 exception 135 [31m[31mInternal Server Error: /user/home[0m[0m
Traceback (most recent call last):
  File "/home/zheng/.virtualenvs/EPGN/lib/python3.5/site-packages/django/core/handlers/exception.py", line 41, in inner
    response = get_response(request)
  File "/home/zheng/.virtualenvs/EPGN/lib/python3.5/site-packages/django/utils/deprecation.py", line 138, in __call__
    response = self.process_request(request)
  File "/home/zheng/.virtualenvs/EPGN/lib/python3.5/site-packages/django/middleware/common.py", line 63, in process_request
    path = self.get_full_path_with_slash(request)
  File "/home/zheng/.virtualenvs/EPGN/lib/python3.5/site-packages/django/middleware/common.py", line 101, in get_full_path_with_slash
    'url': request.get_host() + new_path,
RuntimeError: You called this URL via POST, but the URL doesn't end in a slash and you have APPEND_SLASH set. Django can't redirect to the slash URL while maintaining POST data. Change your form to point to localhost:8899/user/home/ (note the trailing slash), or set APPEND_SLASH=False in your Django settings.
ERROR 2020-10-15 11:00:52,809 basehttp 124 [31m[31m"POST /user/home HTTP/1.1" 500 74270[0m[0m
INFO 2020-10-15 11:01:37,009 basehttp 124 [32m[32m"GET /user/logout/ HTTP/1.1" 200 7152[0m[0m
INFO 2020-10-15 11:01:43,946 basehttp 124 [32m[32m"POST /authorization/ HTTP/1.1" 200 260[0m[0m
INFO 2020-10-15 11:01:44,030 basehttp 124 [32m[32m"GET /user/home/ HTTP/1.1" 200 43508[0m[0m
INFO 2020-10-15 11:01:44,607 basehttp 124 [32m[32m"GET /test/car_platform/ HTTP/1.1" 200 294[0m[0m
INFO 2020-10-15 11:01:44,667 basehttp 124 [32m[32m"POST /user/home/ HTTP/1.1" 200 106[0m[0m
INFO 2020-10-15 11:01:44,774 basehttp 124 [32m[32m"GET /user/user/22/ HTTP/1.1" 200 21529[0m[0m
INFO 2020-10-15 11:01:45,096 basehttp 124 [32m[32m"GET /user/file/22/?page=1&limit=30 HTTP/1.1" 200 48[0m[0m
INFO 2020-10-15 11:01:45,385 basehttp 124 [32m[32m"GET /user/logout/ HTTP/1.1" 200 7152[0m[0m
INFO 2020-10-15 11:14:23,183 basehttp 124 [32m[32m"POST /authorization/ HTTP/1.1" 200 248[0m[0m
INFO 2020-10-15 11:14:23,264 basehttp 124 [32m[32m"GET /user/home/ HTTP/1.1" 200 43508[0m[0m
INFO 2020-10-15 11:14:23,888 basehttp 124 [32m[32m"GET /test/car_platform/ HTTP/1.1" 200 294[0m[0m
INFO 2020-10-15 11:14:24,005 basehttp 124 [32m[32m"POST /user/home/ HTTP/1.1" 200 106[0m[0m
INFO 2020-10-15 11:14:24,160 basehttp 124 [32m[32m"GET /user/user/4/ HTTP/1.1" 200 21526[0m[0m
INFO 2020-10-15 11:14:24,448 basehttp 124 [32m[32m"GET /user/file/4/?page=1&limit=30 HTTP/1.1" 200 48[0m[0m
INFO 2020-10-15 11:14:25,291 basehttp 124 [32m[32m"GET /user/logout/ HTTP/1.1" 200 7152[0m[0m
INFO 2020-10-15 11:14:35,293 basehttp 124 [32m[32m"POST /authorization/ HTTP/1.1" 200 260[0m[0m
INFO 2020-10-15 11:14:35,333 basehttp 124 [32m[32m"GET /user/home/ HTTP/1.1" 200 43508[0m[0m
INFO 2020-10-15 11:14:35,866 basehttp 124 [32m[32m"GET /test/car_platform/ HTTP/1.1" 200 294[0m[0m
INFO 2020-10-15 11:14:35,965 basehttp 124 [32m[32m"POST /user/home/ HTTP/1.1" 200 106[0m[0m
INFO 2020-10-15 11:14:36,107 basehttp 124 [32m[32m"GET /user/user/22/ HTTP/1.1" 200 21529[0m[0m
INFO 2020-10-15 11:14:36,378 basehttp 124 [32m[32m"GET /user/file/22/?page=1&limit=30 HTTP/1.1" 200 48[0m[0m
INFO 2020-10-15 11:14:37,796 basehttp 124 [32m[32m"GET /time/submit/ HTTP/1.1" 200 39663[0m[0m
INFO 2020-10-15 11:14:38,428 basehttp 124 [32m[32m"GET /test/car_platform/ HTTP/1.1" 200 294[0m[0m
INFO 2020-10-15 11:14:38,610 basehttp 124 [32m[32m"GET /time/task/?user_id=22 HTTP/1.1" 200 88[0m[0m
INFO 2020-10-15 11:14:38,759 basehttp 124 [32m[32m"GET /user/user/22/ HTTP/1.1" 200 21529[0m[0m
INFO 2020-10-15 11:14:38,837 basehttp 124 [32m[32m"GET /time/item/?user_id=22 HTTP/1.1" 200 2494[0m[0m
ERROR 2020-10-15 11:14:49,174 exception 135 [31m[31mInternal Server Error: /time/task/[0m[0m
Traceback (most recent call last):
  File "/home/zheng/.virtualenvs/EPGN/lib/python3.5/site-packages/django/core/handlers/exception.py", line 41, in inner
    response = get_response(request)
  File "/home/zheng/.virtualenvs/EPGN/lib/python3.5/site-packages/django/core/handlers/base.py", line 187, in _get_response
    response = self.process_exception_by_middleware(e, request)
  File "/home/zheng/.virtualenvs/EPGN/lib/python3.5/site-packages/django/core/handlers/base.py", line 185, in _get_response
    response = wrapped_callback(request, *callback_args, **callback_kwargs)
  File "/home/zheng/.virtualenvs/EPGN/lib/python3.5/site-packages/django/views/decorators/csrf.py", line 58, in wrapped_view
    return view_func(*args, **kwargs)
  File "/home/zheng/.virtualenvs/EPGN/lib/python3.5/site-packages/rest_framework/viewsets.py", line 114, in view
    return self.dispatch(request, *args, **kwargs)
  File "/home/zheng/.virtualenvs/EPGN/lib/python3.5/site-packages/rest_framework/views.py", line 505, in dispatch
    response = self.handle_exception(exc)
  File "/home/zheng/.virtualenvs/EPGN/lib/python3.5/site-packages/rest_framework/views.py", line 465, in handle_exception
    self.raise_uncaught_exception(exc)
  File "/home/zheng/.virtualenvs/EPGN/lib/python3.5/site-packages/rest_framework/views.py", line 476, in raise_uncaught_exception
    raise exc
  File "/home/zheng/.virtualenvs/EPGN/lib/python3.5/site-packages/rest_framework/views.py", line 502, in dispatch
    response = handler(request, *args, **kwargs)
  File "/home/zheng/Documents/WorkFile/EPGN_INFO/apps/worktime/views.py", line 159, in create
    detail=task["taskDetail"],  #
KeyError: 'taskDetail'
ERROR 2020-10-15 11:14:49,198 basehttp 124 [31m[31m"POST /time/task/ HTTP/1.1" 500 21203[0m[0m
INFO 2020-10-15 12:10:37,578 basehttp 124 [32m[32m"GET /time/submit/ HTTP/1.1" 200 43655[0m[0m
INFO 2020-10-15 12:10:38,398 basehttp 124 [32m[32m"GET /test/car_platform/ HTTP/1.1" 200 294[0m[0m
INFO 2020-10-15 12:10:38,595 basehttp 124 [32m[32m"GET /time/task/?user_id=22 HTTP/1.1" 200 88[0m[0m
INFO 2020-10-15 12:10:38,727 basehttp 124 [32m[32m"GET /user/user/22/ HTTP/1.1" 200 21529[0m[0m
INFO 2020-10-15 12:10:38,928 basehttp 124 [32m[32m"GET /time/item/?user_id=22 HTTP/1.1" 200 2494[0m[0m
INFO 2020-10-15 12:10:39,162 basehttp 124 [32m[32m"GET /favicon.ico HTTP/1.1" 302 0[0m[0m
INFO 2020-10-15 12:10:39,173 basehttp 124 [32m[32m"GET /static/image/favicon.ico HTTP/1.1" 200 67646[0m[0m
INFO 2020-10-15 12:11:01,157 basehttp 124 [32m[32m"POST /time/task/ HTTP/1.1" 200 16[0m[0m
INFO 2020-10-15 12:11:01,205 basehttp 124 [32m[32m"GET /time/task/?user_id=22 HTTP/1.1" 200 928[0m[0m
INFO 2020-10-15 12:11:06,699 basehttp 124 [32m[32m"POST /time/task/ HTTP/1.1" 200 16[0m[0m
INFO 2020-10-15 12:11:06,776 basehttp 124 [32m[32m"GET /time/task/?user_id=22 HTTP/1.1" 200 1770[0m[0m
INFO 2020-10-15 12:11:07,247 basehttp 124 [32m[32m"POST /time/task/ HTTP/1.1" 200 16[0m[0m
INFO 2020-10-15 12:11:07,334 basehttp 124 [32m[32m"GET /time/task/?user_id=22 HTTP/1.1" 200 2612[0m[0m
INFO 2020-10-15 12:11:07,576 basehttp 124 [32m[32m"POST /time/task/ HTTP/1.1" 200 16[0m[0m
INFO 2020-10-15 12:11:07,693 basehttp 124 [32m[32m"GET /time/task/?user_id=22 HTTP/1.1" 200 3454[0m[0m
INFO 2020-10-15 12:11:08,255 basehttp 124 [32m[32m"POST /time/task/ HTTP/1.1" 200 16[0m[0m
INFO 2020-10-15 12:11:08,383 basehttp 124 [32m[32m"GET /time/task/?user_id=22 HTTP/1.1" 200 4297[0m[0m
INFO 2020-10-15 12:11:09,458 basehttp 124 [32m[32m"GET /user/logout/ HTTP/1.1" 200 7152[0m[0m
INFO 2020-10-15 12:11:12,066 basehttp 124 [32m[32m"POST /authorization/ HTTP/1.1" 200 248[0m[0m
INFO 2020-10-15 12:11:12,095 basehttp 124 [32m[32m"GET /user/home/ HTTP/1.1" 200 43508[0m[0m
INFO 2020-10-15 12:11:12,479 basehttp 124 [32m[32m"GET /test/car_platform/ HTTP/1.1" 200 294[0m[0m
ERROR 2020-10-15 12:11:12,551 exception 135 [31m[31mInternal Server Error: /user/home/[0m[0m
Traceback (most recent call last):
  File "/home/zheng/.virtualenvs/EPGN/lib/python3.5/site-packages/django/core/handlers/exception.py", line 41, in inner
    response = get_response(request)
  File "/home/zheng/.virtualenvs/EPGN/lib/python3.5/site-packages/django/core/handlers/base.py", line 187, in _get_response
    response = self.process_exception_by_middleware(e, request)
  File "/home/zheng/.virtualenvs/EPGN/lib/python3.5/site-packages/django/core/handlers/base.py", line 185, in _get_response
    response = wrapped_callback(request, *callback_args, **callback_kwargs)
  File "/home/zheng/Documents/WorkFile/EPGN_INFO/apps/users/views.py", line 170, in home
    return JsonResponse(user_data)
  File "/home/zheng/.virtualenvs/EPGN/lib/python3.5/site-packages/django/http/response.py", line 530, in __init__
    data = json.dumps(data, cls=encoder, **json_dumps_params)
  File "/usr/lib/python3.5/json/__init__.py", line 237, in dumps
    **kw).encode(obj)
  File "/usr/lib/python3.5/json/encoder.py", line 198, in encode
    chunks = self.iterencode(o, _one_shot=True)
  File "/usr/lib/python3.5/json/encoder.py", line 256, in iterencode
    return _iterencode(o, 0)
  File "/home/zheng/.virtualenvs/EPGN/lib/python3.5/site-packages/django/core/serializers/json.py", line 121, in default
    return super(DjangoJSONEncoder, self).default(o)
  File "/usr/lib/python3.5/json/encoder.py", line 179, in default
    raise TypeError(repr(o) + " is not JSON serializable")
TypeError: <Task: 工时审核--苏东弘> is not JSON serializable
ERROR 2020-10-15 12:11:12,577 basehttp 124 [31m[31m"POST /user/home/ HTTP/1.1" 500 20786[0m[0m
INFO 2020-10-15 12:11:12,695 basehttp 124 [32m[32m"GET /user/user/4/ HTTP/1.1" 200 21526[0m[0m
INFO 2020-10-15 12:11:12,927 basehttp 124 [32m[32m"GET /user/file/4/?page=1&limit=30 HTTP/1.1" 200 48[0m[0m
INFO 2020-10-15 12:11:42,667 basehttp 124 [32m[32m"GET /user/home/ HTTP/1.1" 200 43508[0m[0m
INFO 2020-10-15 12:11:43,078 basehttp 124 [32m[32m"GET /test/car_platform/ HTTP/1.1" 200 294[0m[0m
INFO 2020-10-15 12:11:43,124 basehttp 124 [32m[32m"POST /user/home/ HTTP/1.1" 200 344[0m[0m
INFO 2020-10-15 12:11:43,217 basehttp 124 [32m[32m"GET /user/user/4/ HTTP/1.1" 200 21526[0m[0m
INFO 2020-10-15 12:11:43,368 basehttp 124 [32m[32m"GET /user/file/4/?page=1&limit=30 HTTP/1.1" 200 48[0m[0m
INFO 2020-10-15 12:11:43,433 basehttp 124 [32m[32m"GET /favicon.ico HTTP/1.1" 302 0[0m[0m
INFO 2020-10-15 12:11:43,442 basehttp 124 [32m[32m"GET /static/image/favicon.ico HTTP/1.1" 200 67646[0m[0m
ERROR 2020-10-15 12:12:38,910 exception 135 [31m[31mInternal Server Error: /time/work[0m[0m
Traceback (most recent call last):
  File "/home/zheng/.virtualenvs/EPGN/lib/python3.5/site-packages/django/core/handlers/exception.py", line 41, in inner
    response = get_response(request)
  File "/home/zheng/.virtualenvs/EPGN/lib/python3.5/site-packages/django/utils/deprecation.py", line 138, in __call__
    response = self.process_request(request)
  File "/home/zheng/.virtualenvs/EPGN/lib/python3.5/site-packages/django/middleware/common.py", line 63, in process_request
    path = self.get_full_path_with_slash(request)
  File "/home/zheng/.virtualenvs/EPGN/lib/python3.5/site-packages/django/middleware/common.py", line 101, in get_full_path_with_slash
    'url': request.get_host() + new_path,
RuntimeError: You called this URL via POST, but the URL doesn't end in a slash and you have APPEND_SLASH set. Django can't redirect to the slash URL while maintaining POST data. Change your form to point to localhost:8899/time/work/ (note the trailing slash), or set APPEND_SLASH=False in your Django settings.
ERROR 2020-10-15 12:12:38,955 basehttp 124 [31m[31m"POST /time/work HTTP/1.1" 500 74270[0m[0m
INFO 2020-10-15 12:12:48,444 basehttp 124 [32m[32m"GET /time/work HTTP/1.1" 301 0[0m[0m
INFO 2020-10-15 12:12:48,489 basehttp 124 [32m[32m"GET /time/work/ HTTP/1.1" 200 1271[0m[0m
INFO 2020-10-15 12:13:41,625 basehttp 124 [32m[32m"GET /time/work/6/ HTTP/1.1" 200 243[0m[0m
ERROR 2020-10-15 12:19:50,157 exception 135 [31m[31mInternal Server Error: /time/work/[0m[0m
Traceback (most recent call last):
  File "/home/zheng/.virtualenvs/EPGN/lib/python3.5/site-packages/django/core/handlers/exception.py", line 41, in inner
    response = get_response(request)
  File "/home/zheng/.virtualenvs/EPGN/lib/python3.5/site-packages/django/core/handlers/base.py", line 187, in _get_response
    response = self.process_exception_by_middleware(e, request)
  File "/home/zheng/.virtualenvs/EPGN/lib/python3.5/site-packages/django/core/handlers/base.py", line 185, in _get_response
    response = wrapped_callback(request, *callback_args, **callback_kwargs)
  File "/home/zheng/.virtualenvs/EPGN/lib/python3.5/site-packages/django/views/decorators/csrf.py", line 58, in wrapped_view
    return view_func(*args, **kwargs)
  File "/home/zheng/.virtualenvs/EPGN/lib/python3.5/site-packages/rest_framework/viewsets.py", line 114, in view
    return self.dispatch(request, *args, **kwargs)
  File "/home/zheng/.virtualenvs/EPGN/lib/python3.5/site-packages/rest_framework/views.py", line 505, in dispatch
    response = self.handle_exception(exc)
  File "/home/zheng/.virtualenvs/EPGN/lib/python3.5/site-packages/rest_framework/views.py", line 465, in handle_exception
    self.raise_uncaught_exception(exc)
  File "/home/zheng/.virtualenvs/EPGN/lib/python3.5/site-packages/rest_framework/views.py", line 476, in raise_uncaught_exception
    raise exc
  File "/home/zheng/.virtualenvs/EPGN/lib/python3.5/site-packages/rest_framework/views.py", line 502, in dispatch
    response = handler(request, *args, **kwargs)
  File "/home/zheng/Documents/WorkFile/EPGN_INFO/apps/worktime/views.py", line 129, in list
    task = TaskDetail.objects.get_queryset(parent__id=None, task_manager_id=manager_id)
TypeError: get_queryset() got an unexpected keyword argument 'parent__id'
ERROR 2020-10-15 12:19:50,176 basehttp 124 [31m[31m"GET /time/work/?manager_id=4 HTTP/1.1" 500 20551[0m[0m
ERROR 2020-10-15 12:20:11,190 exception 135 [31m[31mInternal Server Error: /time/work/[0m[0m
Traceback (most recent call last):
  File "/home/zheng/.virtualenvs/EPGN/lib/python3.5/site-packages/django/core/handlers/exception.py", line 41, in inner
    response = get_response(request)
  File "/home/zheng/.virtualenvs/EPGN/lib/python3.5/site-packages/django/core/handlers/base.py", line 187, in _get_response
    response = self.process_exception_by_middleware(e, request)
  File "/home/zheng/.virtualenvs/EPGN/lib/python3.5/site-packages/django/core/handlers/base.py", line 185, in _get_response
    response = wrapped_callback(request, *callback_args, **callback_kwargs)
  File "/home/zheng/.virtualenvs/EPGN/lib/python3.5/site-packages/django/views/decorators/csrf.py", line 58, in wrapped_view
    return view_func(*args, **kwargs)
  File "/home/zheng/.virtualenvs/EPGN/lib/python3.5/site-packages/rest_framework/viewsets.py", line 114, in view
    return self.dispatch(request, *args, **kwargs)
  File "/home/zheng/.virtualenvs/EPGN/lib/python3.5/site-packages/rest_framework/views.py", line 505, in dispatch
    response = self.handle_exception(exc)
  File "/home/zheng/.virtualenvs/EPGN/lib/python3.5/site-packages/rest_framework/views.py", line 465, in handle_exception
    self.raise_uncaught_exception(exc)
  File "/home/zheng/.virtualenvs/EPGN/lib/python3.5/site-packages/rest_framework/views.py", line 476, in raise_uncaught_exception
    raise exc
  File "/home/zheng/.virtualenvs/EPGN/lib/python3.5/site-packages/rest_framework/views.py", line 502, in dispatch
    response = handler(request, *args, **kwargs)
  File "/home/zheng/Documents/WorkFile/EPGN_INFO/apps/worktime/views.py", line 129, in list
    task = TaskDetail.objects.filter(parent__id=None, task_manager_id=manager_id)
  File "/home/zheng/.virtualenvs/EPGN/lib/python3.5/site-packages/django/db/models/manager.py", line 85, in manager_method
    return getattr(self.get_queryset(), name)(*args, **kwargs)
  File "/home/zheng/.virtualenvs/EPGN/lib/python3.5/site-packages/django/db/models/query.py", line 781, in filter
    return self._filter_or_exclude(False, *args, **kwargs)
  File "/home/zheng/.virtualenvs/EPGN/lib/python3.5/site-packages/django/db/models/query.py", line 799, in _filter_or_exclude
    clone.query.add_q(Q(*args, **kwargs))
  File "/home/zheng/.virtualenvs/EPGN/lib/python3.5/site-packages/django/db/models/sql/query.py", line 1260, in add_q
    clause, _ = self._add_q(q_object, self.used_aliases)
  File "/home/zheng/.virtualenvs/EPGN/lib/python3.5/site-packages/django/db/models/sql/query.py", line 1286, in _add_q
    allow_joins=allow_joins, split_subq=split_subq,
  File "/home/zheng/.virtualenvs/EPGN/lib/python3.5/site-packages/django/db/models/sql/query.py", line 1164, in build_filter
    lookups, parts, reffed_expression = self.solve_lookup_type(arg)
  File "/home/zheng/.virtualenvs/EPGN/lib/python3.5/site-packages/django/db/models/sql/query.py", line 1044, in solve_lookup_type
    _, field, _, lookup_parts = self.names_to_path(lookup_splitted, self.get_meta())
  File "/home/zheng/.virtualenvs/EPGN/lib/python3.5/site-packages/django/db/models/sql/query.py", line 1362, in names_to_path
    "Choices are: %s" % (name, ", ".join(available)))
django.core.exceptions.FieldError: Cannot resolve keyword 'task_manager_id' into field. Choices are: category, color, detail, hour, id, laboratory, laboratory_id, name, parent, parent_id, role, task_manager
ERROR 2020-10-15 12:20:11,239 basehttp 124 [31m[31m"GET /time/work/?manager_id=4 HTTP/1.1" 500 22271[0m[0m
ERROR 2020-10-15 12:21:22,537 exception 135 [31m[31mInternal Server Error: /time/work/[0m[0m
Traceback (most recent call last):
  File "/home/zheng/.virtualenvs/EPGN/lib/python3.5/site-packages/django/core/handlers/exception.py", line 41, in inner
    response = get_response(request)
  File "/home/zheng/.virtualenvs/EPGN/lib/python3.5/site-packages/django/core/handlers/base.py", line 187, in _get_response
    response = self.process_exception_by_middleware(e, request)
  File "/home/zheng/.virtualenvs/EPGN/lib/python3.5/site-packages/django/core/handlers/base.py", line 185, in _get_response
    response = wrapped_callback(request, *callback_args, **callback_kwargs)
  File "/home/zheng/.virtualenvs/EPGN/lib/python3.5/site-packages/django/views/decorators/csrf.py", line 58, in wrapped_view
    return view_func(*args, **kwargs)
  File "/home/zheng/.virtualenvs/EPGN/lib/python3.5/site-packages/rest_framework/viewsets.py", line 114, in view
    return self.dispatch(request, *args, **kwargs)
  File "/home/zheng/.virtualenvs/EPGN/lib/python3.5/site-packages/rest_framework/views.py", line 505, in dispatch
    response = self.handle_exception(exc)
  File "/home/zheng/.virtualenvs/EPGN/lib/python3.5/site-packages/rest_framework/views.py", line 465, in handle_exception
    self.raise_uncaught_exception(exc)
  File "/home/zheng/.virtualenvs/EPGN/lib/python3.5/site-packages/rest_framework/views.py", line 476, in raise_uncaught_exception
    raise exc
  File "/home/zheng/.virtualenvs/EPGN/lib/python3.5/site-packages/rest_framework/views.py", line 502, in dispatch
    response = handler(request, *args, **kwargs)
  File "/home/zheng/Documents/WorkFile/EPGN_INFO/apps/worktime/views.py", line 134, in list
    work = WorkTask.objects.get(id=item["parent"])
  File "/home/zheng/.virtualenvs/EPGN/lib/python3.5/site-packages/django/db/models/manager.py", line 85, in manager_method
    return getattr(self.get_queryset(), name)(*args, **kwargs)
  File "/home/zheng/.virtualenvs/EPGN/lib/python3.5/site-packages/django/db/models/query.py", line 379, in get
    self.model._meta.object_name
worktime.models.DoesNotExist: WorkTask matching query does not exist.
ERROR 2020-10-15 12:21:22,560 basehttp 124 [31m[31m"GET /time/work/?manager_id=4 HTTP/1.1" 500 20822[0m[0m
ERROR 2020-10-15 12:22:51,374 exception 135 [31m[31mInternal Server Error: /time/work/[0m[0m
Traceback (most recent call last):
  File "/home/zheng/.virtualenvs/EPGN/lib/python3.5/site-packages/django/core/handlers/exception.py", line 41, in inner
    response = get_response(request)
  File "/home/zheng/.virtualenvs/EPGN/lib/python3.5/site-packages/django/core/handlers/base.py", line 187, in _get_response
    response = self.process_exception_by_middleware(e, request)
  File "/home/zheng/.virtualenvs/EPGN/lib/python3.5/site-packages/django/core/handlers/base.py", line 185, in _get_response
    response = wrapped_callback(request, *callback_args, **callback_kwargs)
  File "/home/zheng/.virtualenvs/EPGN/lib/python3.5/site-packages/django/views/decorators/csrf.py", line 58, in wrapped_view
    return view_func(*args, **kwargs)
  File "/home/zheng/.virtualenvs/EPGN/lib/python3.5/site-packages/rest_framework/viewsets.py", line 114, in view
    return self.dispatch(request, *args, **kwargs)
  File "/home/zheng/.virtualenvs/EPGN/lib/python3.5/site-packages/rest_framework/views.py", line 505, in dispatch
    response = self.handle_exception(exc)
  File "/home/zheng/.virtualenvs/EPGN/lib/python3.5/site-packages/rest_framework/views.py", line 465, in handle_exception
    self.raise_uncaught_exception(exc)
  File "/home/zheng/.virtualenvs/EPGN/lib/python3.5/site-packages/rest_framework/views.py", line 476, in raise_uncaught_exception
    raise exc
  File "/home/zheng/.virtualenvs/EPGN/lib/python3.5/site-packages/rest_framework/views.py", line 502, in dispatch
    response = handler(request, *args, **kwargs)
  File "/home/zheng/Documents/WorkFile/EPGN_INFO/apps/worktime/views.py", line 135, in list
    work = WorkTask.objects.get(id=item["parent"])
  File "/home/zheng/.virtualenvs/EPGN/lib/python3.5/site-packages/django/db/models/manager.py", line 85, in manager_method
    return getattr(self.get_queryset(), name)(*args, **kwargs)
  File "/home/zheng/.virtualenvs/EPGN/lib/python3.5/site-packages/django/db/models/query.py", line 379, in get
    self.model._meta.object_name
worktime.models.DoesNotExist: WorkTask matching query does not exist.
ERROR 2020-10-15 12:22:51,409 basehttp 124 [31m[31m"GET /time/work/?manager_id=4 HTTP/1.1" 500 20822[0m[0m
INFO 2020-10-15 12:24:11,167 basehttp 124 [32m[32m"GET /time/work/?manager_id=4 HTTP/1.1" 200 88[0m[0m
ERROR 2020-10-15 12:26:28,280 exception 135 [31m[31mInternal Server Error: /time/work/[0m[0m
Traceback (most recent call last):
  File "/home/zheng/.virtualenvs/EPGN/lib/python3.5/site-packages/django/core/handlers/exception.py", line 41, in inner
    response = get_response(request)
  File "/home/zheng/.virtualenvs/EPGN/lib/python3.5/site-packages/django/core/handlers/base.py", line 187, in _get_response
    response = self.process_exception_by_middleware(e, request)
  File "/home/zheng/.virtualenvs/EPGN/lib/python3.5/site-packages/django/core/handlers/base.py", line 185, in _get_response
    response = wrapped_callback(request, *callback_args, **callback_kwargs)
  File "/home/zheng/.virtualenvs/EPGN/lib/python3.5/site-packages/django/views/decorators/csrf.py", line 58, in wrapped_view
    return view_func(*args, **kwargs)
  File "/home/zheng/.virtualenvs/EPGN/lib/python3.5/site-packages/rest_framework/viewsets.py", line 114, in view
    return self.dispatch(request, *args, **kwargs)
  File "/home/zheng/.virtualenvs/EPGN/lib/python3.5/site-packages/rest_framework/views.py", line 505, in dispatch
    response = self.handle_exception(exc)
  File "/home/zheng/.virtualenvs/EPGN/lib/python3.5/site-packages/rest_framework/views.py", line 465, in handle_exception
    self.raise_uncaught_exception(exc)
  File "/home/zheng/.virtualenvs/EPGN/lib/python3.5/site-packages/rest_framework/views.py", line 476, in raise_uncaught_exception
    raise exc
  File "/home/zheng/.virtualenvs/EPGN/lib/python3.5/site-packages/rest_framework/views.py", line 502, in dispatch
    response = handler(request, *args, **kwargs)
  File "/home/zheng/Documents/WorkFile/EPGN_INFO/apps/worktime/views.py", line 130, in list
    task = TaskDetail.objects.filter(~Q(parent__id='', task_manager=manager))
  File "/home/zheng/.virtualenvs/EPGN/lib/python3.5/site-packages/django/db/models/manager.py", line 85, in manager_method
    return getattr(self.get_queryset(), name)(*args, **kwargs)
  File "/home/zheng/.virtualenvs/EPGN/lib/python3.5/site-packages/django/db/models/query.py", line 781, in filter
    return self._filter_or_exclude(False, *args, **kwargs)
  File "/home/zheng/.virtualenvs/EPGN/lib/python3.5/site-packages/django/db/models/query.py", line 799, in _filter_or_exclude
    clone.query.add_q(Q(*args, **kwargs))
  File "/home/zheng/.virtualenvs/EPGN/lib/python3.5/site-packages/django/db/models/sql/query.py", line 1260, in add_q
    clause, _ = self._add_q(q_object, self.used_aliases)
  File "/home/zheng/.virtualenvs/EPGN/lib/python3.5/site-packages/django/db/models/sql/query.py", line 1280, in _add_q
    current_negated, allow_joins, split_subq)
  File "/home/zheng/.virtualenvs/EPGN/lib/python3.5/site-packages/django/db/models/sql/query.py", line 1286, in _add_q
    allow_joins=allow_joins, split_subq=split_subq,
  File "/home/zheng/.virtualenvs/EPGN/lib/python3.5/site-packages/django/db/models/sql/query.py", line 1220, in build_filter
    condition = self.build_lookup(lookups, col, value)
  File "/home/zheng/.virtualenvs/EPGN/lib/python3.5/site-packages/django/db/models/sql/query.py", line 1114, in build_lookup
    return final_lookup(lhs, rhs)
  File "/home/zheng/.virtualenvs/EPGN/lib/python3.5/site-packages/django/db/models/lookups.py", line 24, in __init__
    self.rhs = self.get_prep_lookup()
  File "/home/zheng/.virtualenvs/EPGN/lib/python3.5/site-packages/django/db/models/lookups.py", line 74, in get_prep_lookup
    return self.lhs.output_field.get_prep_value(self.rhs)
  File "/home/zheng/.virtualenvs/EPGN/lib/python3.5/site-packages/django/db/models/fields/__init__.py", line 962, in get_prep_value
    return int(value)
ValueError: invalid literal for int() with base 10: ''
ERROR 2020-10-15 12:26:28,316 basehttp 124 [31m[31m"GET /time/work/?manager_id=4 HTTP/1.1" 500 22412[0m[0m
INFO 2020-10-15 12:26:43,768 basehttp 124 [32m[32m"GET /time/work/?manager_id=4 HTTP/1.1" 200 88[0m[0m
INFO 2020-10-15 12:27:24,152 basehttp 124 [32m[32m"GET /time/work/?manager_id=4 HTTP/1.1" 200 88[0m[0m
INFO 2020-10-15 12:27:51,101 basehttp 124 [32m[32m"GET /time/work/?manager_id=4 HTTP/1.1" 200 88[0m[0m
INFO 2020-10-15 12:28:53,028 basehttp 124 [32m[32m"GET /time/work/?manager_id=4 HTTP/1.1" 200 88[0m[0m
INFO 2020-10-15 12:29:30,283 basehttp 124 [32m[32m"GET /time/work/?manager_id=4 HTTP/1.1" 200 4297[0m[0m
INFO 2020-10-15 12:31:35,265 basehttp 124 [32m[32m"GET /time/work/?manager_id=4 HTTP/1.1" 200 4297[0m[0m
WARNING 2020-10-15 12:32:27,513 basehttp 124 [33m[33m"PUT /time/work/?manager_id=4&status=2 HTTP/1.1" 405 45[0m[0m
WARNING 2020-10-15 12:32:35,244 basehttp 124 [33m[33m"PATCH /time/work/?manager_id=4&status=2 HTTP/1.1" 405 47[0m[0m
WARNING 2020-10-15 12:33:57,617 basehttp 124 [33m[33m"PUT /time/work/?manager_id=4&status=2 HTTP/1.1" 405 45[0m[0m
WARNING 2020-10-15 12:34:35,569 basehttp 124 [33m[33m"PUT /time/work/ HTTP/1.1" 405 45[0m[0m
WARNING 2020-10-15 12:34:51,485 basehttp 124 [33m[33m"PUT /time/work/6/ HTTP/1.1" 400 192[0m[0m
ERROR 2020-10-15 12:35:33,276 exception 135 [31m[31mInternal Server Error: /time/work/6/[0m[0m
Traceback (most recent call last):
  File "/home/zheng/.virtualenvs/EPGN/lib/python3.5/site-packages/django/core/handlers/exception.py", line 41, in inner
    response = get_response(request)
  File "/home/zheng/.virtualenvs/EPGN/lib/python3.5/site-packages/django/core/handlers/base.py", line 187, in _get_response
    response = self.process_exception_by_middleware(e, request)
  File "/home/zheng/.virtualenvs/EPGN/lib/python3.5/site-packages/django/core/handlers/base.py", line 185, in _get_response
    response = wrapped_callback(request, *callback_args, **callback_kwargs)
  File "/home/zheng/.virtualenvs/EPGN/lib/python3.5/site-packages/django/views/decorators/csrf.py", line 58, in wrapped_view
    return view_func(*args, **kwargs)
  File "/home/zheng/.virtualenvs/EPGN/lib/python3.5/site-packages/rest_framework/viewsets.py", line 114, in view
    return self.dispatch(request, *args, **kwargs)
  File "/home/zheng/.virtualenvs/EPGN/lib/python3.5/site-packages/rest_framework/views.py", line 505, in dispatch
    response = self.handle_exception(exc)
  File "/home/zheng/.virtualenvs/EPGN/lib/python3.5/site-packages/rest_framework/views.py", line 465, in handle_exception
    self.raise_uncaught_exception(exc)
  File "/home/zheng/.virtualenvs/EPGN/lib/python3.5/site-packages/rest_framework/views.py", line 476, in raise_uncaught_exception
    raise exc
  File "/home/zheng/.virtualenvs/EPGN/lib/python3.5/site-packages/rest_framework/views.py", line 502, in dispatch
    response = handler(request, *args, **kwargs)
  File "/home/zheng/Documents/WorkFile/EPGN_INFO/apps/worktime/views.py", line 168, in update
    print(serializer.data)
  File "/home/zheng/.virtualenvs/EPGN/lib/python3.5/site-packages/rest_framework/serializers.py", line 562, in data
    ret = super().data
  File "/home/zheng/.virtualenvs/EPGN/lib/python3.5/site-packages/rest_framework/serializers.py", line 256, in data
    raise AssertionError(msg)
AssertionError: When a serializer is passed a `data` keyword argument you must call `.is_valid()` before attempting to access the serialized `.data` representation.
You should either call `.is_valid()` first, or access `.initial_data` instead.
ERROR 2020-10-15 12:35:33,308 basehttp 124 [31m[31m"PUT /time/work/6/ HTTP/1.1" 500 21105[0m[0m
WARNING 2020-10-15 12:35:53,140 basehttp 124 [33m[33m"PUT /time/work/6/ HTTP/1.1" 400 192[0m[0m
WARNING 2020-10-15 12:36:29,885 basehttp 124 [33m[33m"PUT /time/work/6/ HTTP/1.1" 400 192[0m[0m
ERROR 2020-10-15 12:38:42,834 exception 135 [31m[31mInternal Server Error: /time/work/6/[0m[0m
Traceback (most recent call last):
  File "/home/zheng/.virtualenvs/EPGN/lib/python3.5/site-packages/django/core/handlers/exception.py", line 41, in inner
    response = get_response(request)
  File "/home/zheng/.virtualenvs/EPGN/lib/python3.5/site-packages/django/core/handlers/base.py", line 187, in _get_response
    response = self.process_exception_by_middleware(e, request)
  File "/home/zheng/.virtualenvs/EPGN/lib/python3.5/site-packages/django/core/handlers/base.py", line 185, in _get_response
    response = wrapped_callback(request, *callback_args, **callback_kwargs)
  File "/home/zheng/.virtualenvs/EPGN/lib/python3.5/site-packages/django/views/decorators/csrf.py", line 58, in wrapped_view
    return view_func(*args, **kwargs)
  File "/home/zheng/.virtualenvs/EPGN/lib/python3.5/site-packages/rest_framework/viewsets.py", line 114, in view
    return self.dispatch(request, *args, **kwargs)
  File "/home/zheng/.virtualenvs/EPGN/lib/python3.5/site-packages/rest_framework/views.py", line 505, in dispatch
    response = self.handle_exception(exc)
  File "/home/zheng/.virtualenvs/EPGN/lib/python3.5/site-packages/rest_framework/views.py", line 465, in handle_exception
    self.raise_uncaught_exception(exc)
  File "/home/zheng/.virtualenvs/EPGN/lib/python3.5/site-packages/rest_framework/views.py", line 476, in raise_uncaught_exception
    raise exc
  File "/home/zheng/.virtualenvs/EPGN/lib/python3.5/site-packages/rest_framework/views.py", line 502, in dispatch
    response = handler(request, *args, **kwargs)
  File "/home/zheng/Documents/WorkFile/EPGN_INFO/apps/worktime/views.py", line 172, in update
    instance.check_task = int(check_task)
TypeError: int() argument must be a string, a bytes-like object or a number, not 'NoneType'
ERROR 2020-10-15 12:38:42,858 basehttp 124 [31m[31m"PUT /time/work/6/ HTTP/1.1" 500 20529[0m[0m
ERROR 2020-10-15 12:39:16,962 exception 135 [31m[31mInternal Server Error: /time/work/6/[0m[0m
Traceback (most recent call last):
  File "/home/zheng/.virtualenvs/EPGN/lib/python3.5/site-packages/django/core/handlers/exception.py", line 41, in inner
    response = get_response(request)
  File "/home/zheng/.virtualenvs/EPGN/lib/python3.5/site-packages/django/core/handlers/base.py", line 187, in _get_response
    response = self.process_exception_by_middleware(e, request)
  File "/home/zheng/.virtualenvs/EPGN/lib/python3.5/site-packages/django/core/handlers/base.py", line 185, in _get_response
    response = wrapped_callback(request, *callback_args, **callback_kwargs)
  File "/home/zheng/.virtualenvs/EPGN/lib/python3.5/site-packages/django/views/decorators/csrf.py", line 58, in wrapped_view
    return view_func(*args, **kwargs)
  File "/home/zheng/.virtualenvs/EPGN/lib/python3.5/site-packages/rest_framework/viewsets.py", line 114, in view
    return self.dispatch(request, *args, **kwargs)
  File "/home/zheng/.virtualenvs/EPGN/lib/python3.5/site-packages/rest_framework/views.py", line 505, in dispatch
    response = self.handle_exception(exc)
  File "/home/zheng/.virtualenvs/EPGN/lib/python3.5/site-packages/rest_framework/views.py", line 465, in handle_exception
    self.raise_uncaught_exception(exc)
  File "/home/zheng/.virtualenvs/EPGN/lib/python3.5/site-packages/rest_framework/views.py", line 476, in raise_uncaught_exception
    raise exc
  File "/home/zheng/.virtualenvs/EPGN/lib/python3.5/site-packages/rest_framework/views.py", line 502, in dispatch
    response = handler(request, *args, **kwargs)
  File "/home/zheng/Documents/WorkFile/EPGN_INFO/apps/worktime/views.py", line 172, in update
    instance.check_task = int(status)
TypeError: int() argument must be a string, a bytes-like object or a number, not 'NoneType'
ERROR 2020-10-15 12:39:16,984 basehttp 124 [31m[31m"PUT /time/work/6/ HTTP/1.1" 500 20525[0m[0m
WARNING 2020-10-15 12:41:01,742 basehttp 124 [33m[33m"PUT /time/task/6/ HTTP/1.1" 400 73[0m[0m
WARNING 2020-10-15 12:41:46,561 basehttp 124 [33m[33m"PUT /time/work/6/ HTTP/1.1" 400 82[0m[0m
WARNING 2020-10-15 12:42:01,185 basehttp 124 [33m[33m"PUT /time/work/6/ HTTP/1.1" 400 192[0m[0m
WARNING 2020-10-15 12:42:36,124 basehttp 124 [33m[33m"PUT /time/work/6/ HTTP/1.1" 400 192[0m[0m
ERROR 2020-10-15 12:45:36,022 exception 135 [31m[31mInternal Server Error: /time/work/6/[0m[0m
Traceback (most recent call last):
  File "/home/zheng/.virtualenvs/EPGN/lib/python3.5/site-packages/django/core/handlers/exception.py", line 41, in inner
    response = get_response(request)
  File "/home/zheng/.virtualenvs/EPGN/lib/python3.5/site-packages/django/core/handlers/base.py", line 187, in _get_response
    response = self.process_exception_by_middleware(e, request)
  File "/home/zheng/.virtualenvs/EPGN/lib/python3.5/site-packages/django/core/handlers/base.py", line 185, in _get_response
    response = wrapped_callback(request, *callback_args, **callback_kwargs)
  File "/home/zheng/.virtualenvs/EPGN/lib/python3.5/site-packages/django/views/decorators/csrf.py", line 58, in wrapped_view
    return view_func(*args, **kwargs)
  File "/home/zheng/.virtualenvs/EPGN/lib/python3.5/site-packages/rest_framework/viewsets.py", line 114, in view
    return self.dispatch(request, *args, **kwargs)
  File "/home/zheng/.virtualenvs/EPGN/lib/python3.5/site-packages/rest_framework/views.py", line 505, in dispatch
    response = self.handle_exception(exc)
  File "/home/zheng/.virtualenvs/EPGN/lib/python3.5/site-packages/rest_framework/views.py", line 465, in handle_exception
    self.raise_uncaught_exception(exc)
  File "/home/zheng/.virtualenvs/EPGN/lib/python3.5/site-packages/rest_framework/views.py", line 476, in raise_uncaught_exception
    raise exc
  File "/home/zheng/.virtualenvs/EPGN/lib/python3.5/site-packages/rest_framework/views.py", line 502, in dispatch
    response = handler(request, *args, **kwargs)
  File "/home/zheng/Documents/WorkFile/EPGN_INFO/apps/worktime/views.py", line 175, in update
    return Response(instance.data)
AttributeError: 'WorkTask' object has no attribute 'data'
ERROR 2020-10-15 12:45:36,042 basehttp 124 [31m[31m"PUT /time/work/6/ HTTP/1.1" 500 20454[0m[0m
INFO 2020-10-15 12:45:46,866 basehttp 124 [32m[32m"GET /time/work/6/ HTTP/1.1" 200 243[0m[0m
INFO 2020-10-15 12:46:32,189 basehttp 124 [32m[32m"GET /time/work/?manager_id=4 HTTP/1.1" 200 4297[0m[0m
INFO 2020-10-15 12:47:27,640 basehttp 124 [32m[32m"GET /time/work/6/ HTTP/1.1" 200 243[0m[0m
INFO 2020-10-15 12:47:36,360 basehttp 124 [32m[32m"PATCH /time/work/6/ HTTP/1.1" 200 4[0m[0m
INFO 2020-10-15 12:47:41,737 basehttp 124 [32m[32m"GET /time/work/6/ HTTP/1.1" 200 243[0m[0m
INFO 2020-10-15 12:48:37,015 basehttp 124 [32m[32m"GET /time/work/6/ HTTP/1.1" 200 243[0m[0m
INFO 2020-10-15 12:48:40,725 basehttp 124 [32m[32m"GET /time/work/6/ HTTP/1.1" 200 243[0m[0m
INFO 2020-10-15 12:48:42,596 basehttp 124 [32m[32m"GET /time/work/6/ HTTP/1.1" 200 243[0m[0m
INFO 2020-10-15 12:48:45,618 basehttp 124 [32m[32m"GET /time/work/6/ HTTP/1.1" 200 243[0m[0m
INFO 2020-10-15 12:48:50,756 basehttp 124 [32m[32m"GET /time/work/6/ HTTP/1.1" 200 243[0m[0m
INFO 2020-10-15 12:48:57,790 basehttp 124 [32m[32m"GET /time/work/6/ HTTP/1.1" 200 243[0m[0m
INFO 2020-10-15 12:49:20,871 basehttp 124 [32m[32m"GET /time/work/6/ HTTP/1.1" 200 243[0m[0m
INFO 2020-10-15 12:49:29,607 basehttp 124 [32m[32m"PATCH /time/work/6/ HTTP/1.1" 200 4[0m[0m
INFO 2020-10-15 12:49:32,561 basehttp 124 [32m[32m"GET /time/work/6/ HTTP/1.1" 200 243[0m[0m
WARNING 2020-10-15 12:50:58,508 basehttp 124 [33m[33m"POST /time/work/6/ HTTP/1.1" 405 46[0m[0m
INFO 2020-10-15 12:51:02,990 basehttp 124 [32m[32m"PATCH /time/work/6/ HTTP/1.1" 200 243[0m[0m
INFO 2020-10-15 12:51:09,211 basehttp 124 [32m[32m"PATCH /time/work/6/ HTTP/1.1" 200 243[0m[0m
INFO 2020-10-15 12:53:08,065 basehttp 124 [32m[32m"GET /time/work/?manager_id=4 HTTP/1.1" 200 4297[0m[0m
INFO 2020-10-15 12:56:12,611 basehttp 124 [32m[32m"GET /time/work/?manager_id=4 HTTP/1.1" 200 4297[0m[0m
INFO 2020-10-15 12:58:41,203 basehttp 124 [32m[32m"PATCH /time/work/5/ HTTP/1.1" 200 243[0m[0m
INFO 2020-10-15 12:58:46,536 basehttp 124 [32m[32m"GET /time/work/?manager_id=4 HTTP/1.1" 200 4297[0m[0m
INFO 2020-10-15 13:03:34,684 basehttp 124 [32m[32m"GET /time/work/?manager_id=4 HTTP/1.1" 200 88[0m[0m
INFO 2020-10-15 13:04:02,319 basehttp 124 [32m[32m"GET /time/work/?manager_id=4 HTTP/1.1" 200 4297[0m[0m
ERROR 2020-10-15 13:07:53,199 exception 135 [31m[31mInternal Server Error: /time/work/[0m[0m
Traceback (most recent call last):
  File "/home/zheng/.virtualenvs/EPGN/lib/python3.5/site-packages/django/core/handlers/exception.py", line 41, in inner
    response = get_response(request)
  File "/home/zheng/.virtualenvs/EPGN/lib/python3.5/site-packages/django/core/handlers/base.py", line 187, in _get_response
    response = self.process_exception_by_middleware(e, request)
  File "/home/zheng/.virtualenvs/EPGN/lib/python3.5/site-packages/django/core/handlers/base.py", line 185, in _get_response
    response = wrapped_callback(request, *callback_args, **callback_kwargs)
  File "/home/zheng/.virtualenvs/EPGN/lib/python3.5/site-packages/django/views/decorators/csrf.py", line 58, in wrapped_view
    return view_func(*args, **kwargs)
  File "/home/zheng/.virtualenvs/EPGN/lib/python3.5/site-packages/rest_framework/viewsets.py", line 114, in view
    return self.dispatch(request, *args, **kwargs)
  File "/home/zheng/.virtualenvs/EPGN/lib/python3.5/site-packages/rest_framework/views.py", line 505, in dispatch
    response = self.handle_exception(exc)
  File "/home/zheng/.virtualenvs/EPGN/lib/python3.5/site-packages/rest_framework/views.py", line 465, in handle_exception
    self.raise_uncaught_exception(exc)
  File "/home/zheng/.virtualenvs/EPGN/lib/python3.5/site-packages/rest_framework/views.py", line 476, in raise_uncaught_exception
    raise exc
  File "/home/zheng/.virtualenvs/EPGN/lib/python3.5/site-packages/rest_framework/views.py", line 502, in dispatch
    response = handler(request, *args, **kwargs)
  File "/home/zheng/Documents/WorkFile/EPGN_INFO/apps/worktime/views.py", line 137, in list
    print(item.parent__check_data)
AttributeError: 'collections.OrderedDict' object has no attribute 'parent__check_data'
ERROR 2020-10-15 13:07:53,224 basehttp 124 [31m[31m"GET /time/work/?manager_id=4 HTTP/1.1" 500 20528[0m[0m
ERROR 2020-10-15 13:08:14,122 exception 135 [31m[31mInternal Server Error: /time/work/[0m[0m
Traceback (most recent call last):
  File "/home/zheng/.virtualenvs/EPGN/lib/python3.5/site-packages/django/core/handlers/exception.py", line 41, in inner
    response = get_response(request)
  File "/home/zheng/.virtualenvs/EPGN/lib/python3.5/site-packages/django/core/handlers/base.py", line 187, in _get_response
    response = self.process_exception_by_middleware(e, request)
  File "/home/zheng/.virtualenvs/EPGN/lib/python3.5/site-packages/django/core/handlers/base.py", line 185, in _get_response
    response = wrapped_callback(request, *callback_args, **callback_kwargs)
  File "/home/zheng/.virtualenvs/EPGN/lib/python3.5/site-packages/django/views/decorators/csrf.py", line 58, in wrapped_view
    return view_func(*args, **kwargs)
  File "/home/zheng/.virtualenvs/EPGN/lib/python3.5/site-packages/rest_framework/viewsets.py", line 114, in view
    return self.dispatch(request, *args, **kwargs)
  File "/home/zheng/.virtualenvs/EPGN/lib/python3.5/site-packages/rest_framework/views.py", line 505, in dispatch
    response = self.handle_exception(exc)
  File "/home/zheng/.virtualenvs/EPGN/lib/python3.5/site-packages/rest_framework/views.py", line 465, in handle_exception
    self.raise_uncaught_exception(exc)
  File "/home/zheng/.virtualenvs/EPGN/lib/python3.5/site-packages/rest_framework/views.py", line 476, in raise_uncaught_exception
    raise exc
  File "/home/zheng/.virtualenvs/EPGN/lib/python3.5/site-packages/rest_framework/views.py", line 502, in dispatch
    response = handler(request, *args, **kwargs)
  File "/home/zheng/Documents/WorkFile/EPGN_INFO/apps/worktime/views.py", line 137, in list
    print(item["parent__check_data"])
KeyError: 'parent__check_data'
ERROR 2020-10-15 13:08:14,141 basehttp 124 [31m[31m"GET /time/work/?manager_id=4 HTTP/1.1" 500 20419[0m[0m
INFO 2020-10-15 13:09:41,229 basehttp 124 [32m[32m"GET /time/work/?manager_id=4 HTTP/1.1" 200 4297[0m[0m
ERROR 2020-10-15 13:11:12,488 exception 135 [31m[31mInternal Server Error: /time/work/[0m[0m
Traceback (most recent call last):
  File "/home/zheng/.virtualenvs/EPGN/lib/python3.5/site-packages/django/core/handlers/exception.py", line 41, in inner
    response = get_response(request)
  File "/home/zheng/.virtualenvs/EPGN/lib/python3.5/site-packages/django/core/handlers/base.py", line 187, in _get_response
    response = self.process_exception_by_middleware(e, request)
  File "/home/zheng/.virtualenvs/EPGN/lib/python3.5/site-packages/django/core/handlers/base.py", line 185, in _get_response
    response = wrapped_callback(request, *callback_args, **callback_kwargs)
  File "/home/zheng/.virtualenvs/EPGN/lib/python3.5/site-packages/django/views/decorators/csrf.py", line 58, in wrapped_view
    return view_func(*args, **kwargs)
  File "/home/zheng/.virtualenvs/EPGN/lib/python3.5/site-packages/rest_framework/viewsets.py", line 114, in view
    return self.dispatch(request, *args, **kwargs)
  File "/home/zheng/.virtualenvs/EPGN/lib/python3.5/site-packages/rest_framework/views.py", line 505, in dispatch
    response = self.handle_exception(exc)
  File "/home/zheng/.virtualenvs/EPGN/lib/python3.5/site-packages/rest_framework/views.py", line 465, in handle_exception
    self.raise_uncaught_exception(exc)
  File "/home/zheng/.virtualenvs/EPGN/lib/python3.5/site-packages/rest_framework/views.py", line 476, in raise_uncaught_exception
    raise exc
  File "/home/zheng/.virtualenvs/EPGN/lib/python3.5/site-packages/rest_framework/views.py", line 502, in dispatch
    response = handler(request, *args, **kwargs)
  File "/home/zheng/Documents/WorkFile/EPGN_INFO/apps/worktime/views.py", line 132, in list
    task_list = TaskDetail.objects.filter(~Q(parent__id=None)).filter(work_task__check_data=2, task_manager=manager)
  File "/home/zheng/.virtualenvs/EPGN/lib/python3.5/site-packages/django/db/models/query.py", line 781, in filter
    return self._filter_or_exclude(False, *args, **kwargs)
  File "/home/zheng/.virtualenvs/EPGN/lib/python3.5/site-packages/django/db/models/query.py", line 799, in _filter_or_exclude
    clone.query.add_q(Q(*args, **kwargs))
  File "/home/zheng/.virtualenvs/EPGN/lib/python3.5/site-packages/django/db/models/sql/query.py", line 1260, in add_q
    clause, _ = self._add_q(q_object, self.used_aliases)
  File "/home/zheng/.virtualenvs/EPGN/lib/python3.5/site-packages/django/db/models/sql/query.py", line 1286, in _add_q
    allow_joins=allow_joins, split_subq=split_subq,
  File "/home/zheng/.virtualenvs/EPGN/lib/python3.5/site-packages/django/db/models/sql/query.py", line 1164, in build_filter
    lookups, parts, reffed_expression = self.solve_lookup_type(arg)
  File "/home/zheng/.virtualenvs/EPGN/lib/python3.5/site-packages/django/db/models/sql/query.py", line 1044, in solve_lookup_type
    _, field, _, lookup_parts = self.names_to_path(lookup_splitted, self.get_meta())
  File "/home/zheng/.virtualenvs/EPGN/lib/python3.5/site-packages/django/db/models/sql/query.py", line 1362, in names_to_path
    "Choices are: %s" % (name, ", ".join(available)))
django.core.exceptions.FieldError: Cannot resolve keyword 'work_task' into field. Choices are: category, color, detail, hour, id, laboratory, laboratory_id, name, parent, parent_id, role, task_manager
ERROR 2020-10-15 13:11:12,555 basehttp 124 [31m[31m"GET /time/work/?manager_id=4 HTTP/1.1" 500 22101[0m[0m
INFO 2020-10-15 13:11:48,832 basehttp 124 [32m[32m"GET /time/work/?manager_id=4 HTTP/1.1" 200 1770[0m[0m
INFO 2020-10-15 13:12:41,411 basehttp 124 [32m[32m"GET /time/work/?manager_id=4 HTTP/1.1" 200 2612[0m[0m
INFO 2020-10-15 13:13:07,927 basehttp 124 [32m[32m"PATCH /time/work/4/ HTTP/1.1" 200 16[0m[0m
INFO 2020-10-15 13:13:15,179 basehttp 124 [32m[32m"GET /time/work/?manager_id=4 HTTP/1.1" 200 1770[0m[0m
INFO 2020-10-15 13:15:02,721 basehttp 124 [32m[32m"GET /user/home/ HTTP/1.1" 200 43508[0m[0m
INFO 2020-10-15 13:15:03,273 basehttp 124 [32m[32m"GET /test/car_platform/ HTTP/1.1" 200 294[0m[0m
INFO 2020-10-15 13:15:03,373 basehttp 124 [32m[32m"POST /user/home/ HTTP/1.1" 200 344[0m[0m
INFO 2020-10-15 13:15:03,487 basehttp 124 [32m[32m"GET /user/user/4/ HTTP/1.1" 200 21526[0m[0m
INFO 2020-10-15 13:15:03,659 basehttp 124 [32m[32m"GET /user/file/4/?page=1&limit=30 HTTP/1.1" 200 48[0m[0m
INFO 2020-10-15 13:15:03,752 basehttp 124 [32m[32m"GET /favicon.ico HTTP/1.1" 302 0[0m[0m
INFO 2020-10-15 13:15:03,761 basehttp 124 [32m[32m"GET /static/image/favicon.ico HTTP/1.1" 200 67646[0m[0m
INFO 2020-10-15 13:15:08,118 basehttp 124 [32m[32m"GET /user/logout/ HTTP/1.1" 200 7152[0m[0m
INFO 2020-10-15 13:15:11,167 basehttp 124 [32m[32m"POST /authorization/ HTTP/1.1" 200 260[0m[0m
INFO 2020-10-15 13:15:11,195 basehttp 124 [32m[32m"GET /user/home/ HTTP/1.1" 200 43508[0m[0m
INFO 2020-10-15 13:15:11,542 basehttp 124 [32m[32m"GET /test/car_platform/ HTTP/1.1" 200 294[0m[0m
INFO 2020-10-15 13:15:11,599 basehttp 124 [32m[32m"POST /user/home/ HTTP/1.1" 200 106[0m[0m
INFO 2020-10-15 13:15:11,696 basehttp 124 [32m[32m"GET /user/user/22/ HTTP/1.1" 200 21529[0m[0m
INFO 2020-10-15 13:15:11,845 basehttp 124 [32m[32m"GET /user/file/22/?page=1&limit=30 HTTP/1.1" 200 48[0m[0m
INFO 2020-10-15 13:15:12,694 basehttp 124 [32m[32m"GET /time/submit/ HTTP/1.1" 200 43655[0m[0m
INFO 2020-10-15 13:15:13,049 basehttp 124 [32m[32m"GET /test/car_platform/ HTTP/1.1" 200 294[0m[0m
INFO 2020-10-15 13:15:13,332 basehttp 124 [32m[32m"GET /user/user/22/ HTTP/1.1" 200 21529[0m[0m
INFO 2020-10-15 13:15:13,484 basehttp 124 [32m[32m"GET /time/task/?user_id=22 HTTP/1.1" 200 4297[0m[0m
INFO 2020-10-15 13:15:13,511 basehttp 124 [32m[32m"GET /time/item/?user_id=22 HTTP/1.1" 200 2494[0m[0m
INFO 2020-10-15 13:21:38,452 basehttp 124 [32m[32m"GET /user/home/ HTTP/1.1" 200 43508[0m[0m
INFO 2020-10-15 13:21:38,830 basehttp 124 [32m[32m"GET /test/car_platform/ HTTP/1.1" 200 294[0m[0m
INFO 2020-10-15 13:21:38,918 basehttp 124 [32m[32m"GET /user/user/22/ HTTP/1.1" 200 21529[0m[0m
INFO 2020-10-15 13:21:38,964 basehttp 124 [32m[32m"POST /user/home/ HTTP/1.1" 200 106[0m[0m
INFO 2020-10-15 13:21:39,232 basehttp 124 [32m[32m"GET /user/file/22/?page=1&limit=30 HTTP/1.1" 200 48[0m[0m
INFO 2020-10-15 13:22:53,811 basehttp 124 [32m[32m"GET /time/submit/ HTTP/1.1" 200 43655[0m[0m
INFO 2020-10-15 13:22:54,203 basehttp 124 [32m[32m"GET /test/car_platform/ HTTP/1.1" 200 294[0m[0m
INFO 2020-10-15 13:22:54,289 basehttp 124 [32m[32m"GET /user/user/22/ HTTP/1.1" 200 21529[0m[0m
INFO 2020-10-15 13:22:54,683 basehttp 124 [32m[32m"GET /time/task/?user_id=22 HTTP/1.1" 200 4297[0m[0m
INFO 2020-10-15 13:22:54,700 basehttp 124 [32m[32m"GET /time/item/?user_id=22 HTTP/1.1" 200 2494[0m[0m
INFO 2020-10-15 13:23:43,860 basehttp 124 [32m[32m"GET /user/home/ HTTP/1.1" 200 43508[0m[0m
INFO 2020-10-15 13:23:44,280 basehttp 124 [32m[32m"GET /test/car_platform/ HTTP/1.1" 200 294[0m[0m
INFO 2020-10-15 13:23:44,357 basehttp 124 [32m[32m"GET /user/user/22/ HTTP/1.1" 200 21529[0m[0m
INFO 2020-10-15 13:23:44,404 basehttp 124 [32m[32m"POST /user/home/ HTTP/1.1" 200 106[0m[0m
INFO 2020-10-15 13:23:44,619 basehttp 124 [32m[32m"GET /user/file/22/?page=1&limit=30 HTTP/1.1" 200 48[0m[0m
