ERROR 2020-06-02 10:33:39,607 exception 135 Internal Server Error: /channelList/
Traceback (most recent call last):
  File "/home/small-spider/.virtualenvs/Working/lib/python3.6/site-packages/django/core/handlers/exception.py", line 41, in inner
    response = get_response(request)
  File "/home/small-spider/.virtualenvs/Working/lib/python3.6/site-packages/django/core/handlers/base.py", line 187, in _get_response
    response = self.process_exception_by_middleware(e, request)
  File "/home/small-spider/.virtualenvs/Working/lib/python3.6/site-packages/django/core/handlers/base.py", line 185, in _get_response
    response = wrapped_callback(request, *callback_args, **callback_kwargs)
  File "/home/small-spider/.virtualenvs/Working/lib/python3.6/site-packages/django/views/generic/base.py", line 68, in view
    return self.dispatch(request, *args, **kwargs)
  File "/home/small-spider/.virtualenvs/Working/lib/python3.6/site-packages/django/views/generic/base.py", line 88, in dispatch
    return handler(request, *args, **kwargs)
  File "/home/small-spider/Documents/项目文件/线上版本/EPGN_INFO_4.17/apps/calculate/views.py", line 33, in put
    channel_dict, items = read_hdf(file_name)
  File "./scripts/readHDF.py", line 12, in read_hdf
    read_info = h5py.File(file_path, 'r')
  File "/home/small-spider/.virtualenvs/Working/lib/python3.6/site-packages/h5py/_hl/files.py", line 408, in __init__
    swmr=swmr)
  File "/home/small-spider/.virtualenvs/Working/lib/python3.6/site-packages/h5py/_hl/files.py", line 173, in make_fid
    fid = h5f.open(name, flags, fapl=fapl)
  File "h5py/_objects.pyx", line 54, in h5py._objects.with_phil.wrapper
  File "h5py/_objects.pyx", line 55, in h5py._objects.with_phil.wrapper
  File "h5py/h5f.pyx", line 88, in h5py.h5f.open
OSError: Unable to open file (unable to open file: name = '/home/zheng/Documents/WorkFile/R_HDF/2020-05-18_KP 80-20kmph run04.hdf', errno = 2, error message = 'No such file or directory', flags = 0, o_flags = 0)
ERROR 2020-06-02 10:33:49,510 exception 135 Internal Server Error: /channelList/
Traceback (most recent call last):
  File "/home/small-spider/.virtualenvs/Working/lib/python3.6/site-packages/django/core/handlers/exception.py", line 41, in inner
    response = get_response(request)
  File "/home/small-spider/.virtualenvs/Working/lib/python3.6/site-packages/django/core/handlers/base.py", line 187, in _get_response
    response = self.process_exception_by_middleware(e, request)
  File "/home/small-spider/.virtualenvs/Working/lib/python3.6/site-packages/django/core/handlers/base.py", line 185, in _get_response
    response = wrapped_callback(request, *callback_args, **callback_kwargs)
  File "/home/small-spider/.virtualenvs/Working/lib/python3.6/site-packages/django/views/generic/base.py", line 68, in view
    return self.dispatch(request, *args, **kwargs)
  File "/home/small-spider/.virtualenvs/Working/lib/python3.6/site-packages/django/views/generic/base.py", line 88, in dispatch
    return handler(request, *args, **kwargs)
  File "/home/small-spider/Documents/项目文件/线上版本/EPGN_INFO_4.17/apps/calculate/views.py", line 33, in put
    channel_dict, items = read_hdf(file_name)
  File "./scripts/readHDF.py", line 12, in read_hdf
    read_info = h5py.File(file_path, 'r')
  File "/home/small-spider/.virtualenvs/Working/lib/python3.6/site-packages/h5py/_hl/files.py", line 408, in __init__
    swmr=swmr)
  File "/home/small-spider/.virtualenvs/Working/lib/python3.6/site-packages/h5py/_hl/files.py", line 173, in make_fid
    fid = h5f.open(name, flags, fapl=fapl)
  File "h5py/_objects.pyx", line 54, in h5py._objects.with_phil.wrapper
  File "h5py/_objects.pyx", line 55, in h5py._objects.with_phil.wrapper
  File "h5py/h5f.pyx", line 88, in h5py.h5f.open
OSError: Unable to open file (unable to open file: name = '/home/zheng/Documents/WorkFile/R_HDF/2020-05-18_KP 80-20kmph run01.hdf', errno = 2, error message = 'No such file or directory', flags = 0, o_flags = 0)
ERROR 2020-06-02 10:34:36,434 exception 135 Internal Server Error: /channelList/
Traceback (most recent call last):
  File "/home/small-spider/.virtualenvs/Working/lib/python3.6/site-packages/django/core/handlers/exception.py", line 41, in inner
    response = get_response(request)
  File "/home/small-spider/.virtualenvs/Working/lib/python3.6/site-packages/django/core/handlers/base.py", line 187, in _get_response
    response = self.process_exception_by_middleware(e, request)
  File "/home/small-spider/.virtualenvs/Working/lib/python3.6/site-packages/django/core/handlers/base.py", line 185, in _get_response
    response = wrapped_callback(request, *callback_args, **callback_kwargs)
  File "/home/small-spider/.virtualenvs/Working/lib/python3.6/site-packages/django/views/generic/base.py", line 68, in view
    return self.dispatch(request, *args, **kwargs)
  File "/home/small-spider/.virtualenvs/Working/lib/python3.6/site-packages/django/views/generic/base.py", line 88, in dispatch
    return handler(request, *args, **kwargs)
  File "/home/small-spider/Documents/项目文件/线上版本/EPGN_INFO_4.17/apps/calculate/views.py", line 33, in put
    channel_dict, items = read_hdf(file_name)
  File "./scripts/readHDF.py", line 12, in read_hdf
    read_info = h5py.File(file_path, 'r')
  File "/home/small-spider/.virtualenvs/Working/lib/python3.6/site-packages/h5py/_hl/files.py", line 408, in __init__
    swmr=swmr)
  File "/home/small-spider/.virtualenvs/Working/lib/python3.6/site-packages/h5py/_hl/files.py", line 173, in make_fid
    fid = h5f.open(name, flags, fapl=fapl)
  File "h5py/_objects.pyx", line 54, in h5py._objects.with_phil.wrapper
  File "h5py/_objects.pyx", line 55, in h5py._objects.with_phil.wrapper
  File "h5py/h5f.pyx", line 88, in h5py.h5f.open
OSError: Unable to open file (unable to open file: name = '/home/zheng/Documents/WorkFile/R_HDF/2020-05-21_KP 42-20kmph run05.hdf', errno = 2, error message = 'No such file or directory', flags = 0, o_flags = 0)
ERROR 2020-06-02 10:34:58,883 exception 135 Internal Server Error: /channelList/
Traceback (most recent call last):
  File "/home/small-spider/.virtualenvs/Working/lib/python3.6/site-packages/django/core/handlers/exception.py", line 41, in inner
    response = get_response(request)
  File "/home/small-spider/.virtualenvs/Working/lib/python3.6/site-packages/django/core/handlers/base.py", line 187, in _get_response
    response = self.process_exception_by_middleware(e, request)
  File "/home/small-spider/.virtualenvs/Working/lib/python3.6/site-packages/django/core/handlers/base.py", line 185, in _get_response
    response = wrapped_callback(request, *callback_args, **callback_kwargs)
  File "/home/small-spider/.virtualenvs/Working/lib/python3.6/site-packages/django/views/generic/base.py", line 68, in view
    return self.dispatch(request, *args, **kwargs)
  File "/home/small-spider/.virtualenvs/Working/lib/python3.6/site-packages/django/views/generic/base.py", line 88, in dispatch
    return handler(request, *args, **kwargs)
  File "/home/small-spider/Documents/项目文件/线上版本/EPGN_INFO_4.17/apps/calculate/views.py", line 33, in put
    channel_dict, items = read_hdf(file_name)
  File "./scripts/readHDF.py", line 12, in read_hdf
    read_info = h5py.File(file_path, 'r')
  File "/home/small-spider/.virtualenvs/Working/lib/python3.6/site-packages/h5py/_hl/files.py", line 408, in __init__
    swmr=swmr)
  File "/home/small-spider/.virtualenvs/Working/lib/python3.6/site-packages/h5py/_hl/files.py", line 173, in make_fid
    fid = h5f.open(name, flags, fapl=fapl)
  File "h5py/_objects.pyx", line 54, in h5py._objects.with_phil.wrapper
  File "h5py/_objects.pyx", line 55, in h5py._objects.with_phil.wrapper
  File "h5py/h5f.pyx", line 88, in h5py.h5f.open
OSError: Unable to open file (unable to open file: name = '/home/zheng/Documents/WorkFile/R_HDF/2020-05-21_KP 42-20kmph run05.hdf', errno = 2, error message = 'No such file or directory', flags = 0, o_flags = 0)
ERROR 2020-06-02 10:35:50,551 exception 135 Internal Server Error: /channelList/
Traceback (most recent call last):
  File "/home/small-spider/.virtualenvs/Working/lib/python3.6/site-packages/django/core/handlers/exception.py", line 41, in inner
    response = get_response(request)
  File "/home/small-spider/.virtualenvs/Working/lib/python3.6/site-packages/django/core/handlers/base.py", line 187, in _get_response
    response = self.process_exception_by_middleware(e, request)
  File "/home/small-spider/.virtualenvs/Working/lib/python3.6/site-packages/django/core/handlers/base.py", line 185, in _get_response
    response = wrapped_callback(request, *callback_args, **callback_kwargs)
  File "/home/small-spider/.virtualenvs/Working/lib/python3.6/site-packages/django/views/generic/base.py", line 68, in view
    return self.dispatch(request, *args, **kwargs)
  File "/home/small-spider/.virtualenvs/Working/lib/python3.6/site-packages/django/views/generic/base.py", line 88, in dispatch
    return handler(request, *args, **kwargs)
  File "/home/small-spider/Documents/项目文件/线上版本/EPGN_INFO_4.17/apps/calculate/views.py", line 33, in put
    channel_dict, items = read_hdf(file_name)
  File "./scripts/readHDF.py", line 12, in read_hdf
    read_info = h5py.File(file_path, 'r')
  File "/home/small-spider/.virtualenvs/Working/lib/python3.6/site-packages/h5py/_hl/files.py", line 408, in __init__
    swmr=swmr)
  File "/home/small-spider/.virtualenvs/Working/lib/python3.6/site-packages/h5py/_hl/files.py", line 173, in make_fid
    fid = h5f.open(name, flags, fapl=fapl)
  File "h5py/_objects.pyx", line 54, in h5py._objects.with_phil.wrapper
  File "h5py/_objects.pyx", line 55, in h5py._objects.with_phil.wrapper
  File "h5py/h5f.pyx", line 88, in h5py.h5f.open
OSError: Unable to open file (unable to open file: name = '/media/sf_Y_DRIVE/Database/R_HDF/2020-05-21_KP 42-20kmph run05.hdf', errno = 2, error message = 'No such file or directory', flags = 0, o_flags = 0)
ERROR 2020-06-02 10:36:01,885 exception 135 Internal Server Error: /channelList/
Traceback (most recent call last):
  File "/home/small-spider/.virtualenvs/Working/lib/python3.6/site-packages/django/core/handlers/exception.py", line 41, in inner
    response = get_response(request)
  File "/home/small-spider/.virtualenvs/Working/lib/python3.6/site-packages/django/core/handlers/base.py", line 187, in _get_response
    response = self.process_exception_by_middleware(e, request)
  File "/home/small-spider/.virtualenvs/Working/lib/python3.6/site-packages/django/core/handlers/base.py", line 185, in _get_response
    response = wrapped_callback(request, *callback_args, **callback_kwargs)
  File "/home/small-spider/.virtualenvs/Working/lib/python3.6/site-packages/django/views/generic/base.py", line 68, in view
    return self.dispatch(request, *args, **kwargs)
  File "/home/small-spider/.virtualenvs/Working/lib/python3.6/site-packages/django/views/generic/base.py", line 88, in dispatch
    return handler(request, *args, **kwargs)
  File "/home/small-spider/Documents/项目文件/线上版本/EPGN_INFO_4.17/apps/calculate/views.py", line 33, in put
    channel_dict, items = read_hdf(file_name)
  File "./scripts/readHDF.py", line 12, in read_hdf
    read_info = h5py.File(file_path, 'r')
  File "/home/small-spider/.virtualenvs/Working/lib/python3.6/site-packages/h5py/_hl/files.py", line 408, in __init__
    swmr=swmr)
  File "/home/small-spider/.virtualenvs/Working/lib/python3.6/site-packages/h5py/_hl/files.py", line 173, in make_fid
    fid = h5f.open(name, flags, fapl=fapl)
  File "h5py/_objects.pyx", line 54, in h5py._objects.with_phil.wrapper
  File "h5py/_objects.pyx", line 55, in h5py._objects.with_phil.wrapper
  File "h5py/h5f.pyx", line 88, in h5py.h5f.open
OSError: Unable to open file (unable to open file: name = '/media/sf_Y_DRIVE/Database/R_HDF/2020-05-18_D ohneAC run03.hdf', errno = 2, error message = 'No such file or directory', flags = 0, o_flags = 0)
ERROR 2020-06-02 10:36:57,209 exception 135 Internal Server Error: /channelList/
Traceback (most recent call last):
  File "/home/small-spider/.virtualenvs/Working/lib/python3.6/site-packages/django/core/handlers/exception.py", line 41, in inner
    response = get_response(request)
  File "/home/small-spider/.virtualenvs/Working/lib/python3.6/site-packages/django/core/handlers/base.py", line 187, in _get_response
    response = self.process_exception_by_middleware(e, request)
  File "/home/small-spider/.virtualenvs/Working/lib/python3.6/site-packages/django/core/handlers/base.py", line 185, in _get_response
    response = wrapped_callback(request, *callback_args, **callback_kwargs)
  File "/home/small-spider/.virtualenvs/Working/lib/python3.6/site-packages/django/views/generic/base.py", line 68, in view
    return self.dispatch(request, *args, **kwargs)
  File "/home/small-spider/.virtualenvs/Working/lib/python3.6/site-packages/django/views/generic/base.py", line 88, in dispatch
    return handler(request, *args, **kwargs)
  File "/home/small-spider/Documents/项目文件/线上版本/EPGN_INFO_4.17/apps/calculate/views.py", line 33, in put
    channel_dict, items = read_hdf(file_name)
  File "./scripts/readHDF.py", line 12, in read_hdf
    read_info = h5py.File(file_path, 'r')
  File "/home/small-spider/.virtualenvs/Working/lib/python3.6/site-packages/h5py/_hl/files.py", line 408, in __init__
    swmr=swmr)
  File "/home/small-spider/.virtualenvs/Working/lib/python3.6/site-packages/h5py/_hl/files.py", line 173, in make_fid
    fid = h5f.open(name, flags, fapl=fapl)
  File "h5py/_objects.pyx", line 54, in h5py._objects.with_phil.wrapper
  File "h5py/_objects.pyx", line 55, in h5py._objects.with_phil.wrapper
  File "h5py/h5f.pyx", line 88, in h5py.h5f.open
OSError: Unable to open file (unable to open file: name = '/media/sf_Y_DRIVE/Database/R_HDF/2020-05-18_D ohneAC run03.hdf', errno = 2, error message = 'No such file or directory', flags = 0, o_flags = 0)
ERROR 2020-06-02 10:43:23,125 exception 135 Internal Server Error: /channelList/
Traceback (most recent call last):
  File "/home/small-spider/.virtualenvs/Working/lib/python3.6/site-packages/django/core/handlers/exception.py", line 41, in inner
    response = get_response(request)
  File "/home/small-spider/.virtualenvs/Working/lib/python3.6/site-packages/django/core/handlers/base.py", line 187, in _get_response
    response = self.process_exception_by_middleware(e, request)
  File "/home/small-spider/.virtualenvs/Working/lib/python3.6/site-packages/django/core/handlers/base.py", line 185, in _get_response
    response = wrapped_callback(request, *callback_args, **callback_kwargs)
  File "/home/small-spider/.virtualenvs/Working/lib/python3.6/site-packages/django/views/generic/base.py", line 68, in view
    return self.dispatch(request, *args, **kwargs)
  File "/home/small-spider/.virtualenvs/Working/lib/python3.6/site-packages/django/views/generic/base.py", line 88, in dispatch
    return handler(request, *args, **kwargs)
  File "/home/small-spider/Documents/项目文件/线上版本/EPGN_INFO_4.17/apps/calculate/views.py", line 69, in post
    file_name = data["file_name"]
TypeError: string indices must be integers
ERROR 2020-06-02 10:46:53,812 exception 135 Internal Server Error: /channelList/
Traceback (most recent call last):
  File "/home/small-spider/.virtualenvs/Working/lib/python3.6/site-packages/django/core/handlers/exception.py", line 41, in inner
    response = get_response(request)
  File "/home/small-spider/.virtualenvs/Working/lib/python3.6/site-packages/django/core/handlers/base.py", line 187, in _get_response
    response = self.process_exception_by_middleware(e, request)
  File "/home/small-spider/.virtualenvs/Working/lib/python3.6/site-packages/django/core/handlers/base.py", line 185, in _get_response
    response = wrapped_callback(request, *callback_args, **callback_kwargs)
  File "/home/small-spider/.virtualenvs/Working/lib/python3.6/site-packages/django/views/generic/base.py", line 68, in view
    return self.dispatch(request, *args, **kwargs)
  File "/home/small-spider/.virtualenvs/Working/lib/python3.6/site-packages/django/views/generic/base.py", line 88, in dispatch
    return handler(request, *args, **kwargs)
  File "/home/small-spider/Documents/项目文件/线上版本/EPGN_INFO_4.17/apps/calculate/views.py", line 69, in post
    file_name = data["file_name"]
TypeError: string indices must be integers
ERROR 2020-06-02 10:49:23,918 exception 135 Internal Server Error: /channelList/
Traceback (most recent call last):
  File "/home/small-spider/.virtualenvs/Working/lib/python3.6/site-packages/django/core/handlers/exception.py", line 41, in inner
    response = get_response(request)
  File "/home/small-spider/.virtualenvs/Working/lib/python3.6/site-packages/django/core/handlers/base.py", line 187, in _get_response
    response = self.process_exception_by_middleware(e, request)
  File "/home/small-spider/.virtualenvs/Working/lib/python3.6/site-packages/django/core/handlers/base.py", line 185, in _get_response
    response = wrapped_callback(request, *callback_args, **callback_kwargs)
  File "/home/small-spider/.virtualenvs/Working/lib/python3.6/site-packages/django/views/generic/base.py", line 68, in view
    return self.dispatch(request, *args, **kwargs)
  File "/home/small-spider/.virtualenvs/Working/lib/python3.6/site-packages/django/views/generic/base.py", line 88, in dispatch
    return handler(request, *args, **kwargs)
  File "/home/small-spider/Documents/项目文件/线上版本/EPGN_INFO_4.17/apps/calculate/views.py", line 69, in post
    file_name = data["file_name"]
TypeError: string indices must be integers
ERROR 2020-06-02 11:21:21,732 exception 135 Internal Server Error: /channelList/
Traceback (most recent call last):
  File "/home/small-spider/.virtualenvs/Working/lib/python3.6/site-packages/django/core/handlers/exception.py", line 41, in inner
    response = get_response(request)
  File "/home/small-spider/.virtualenvs/Working/lib/python3.6/site-packages/django/core/handlers/base.py", line 187, in _get_response
    response = self.process_exception_by_middleware(e, request)
  File "/home/small-spider/.virtualenvs/Working/lib/python3.6/site-packages/django/core/handlers/base.py", line 185, in _get_response
    response = wrapped_callback(request, *callback_args, **callback_kwargs)
  File "/home/small-spider/.virtualenvs/Working/lib/python3.6/site-packages/django/views/generic/base.py", line 68, in view
    return self.dispatch(request, *args, **kwargs)
  File "/home/small-spider/.virtualenvs/Working/lib/python3.6/site-packages/django/views/generic/base.py", line 88, in dispatch
    return handler(request, *args, **kwargs)
  File "/home/small-spider/Documents/项目文件/线上版本/EPGN_INFO_4.17/apps/calculate/views.py", line 63, in post
    data_list = json.loads(body_str)["file_info"]
KeyError: 'file_info'
ERROR 2020-06-02 11:21:49,798 exception 135 Internal Server Error: /channelList/
Traceback (most recent call last):
  File "/home/small-spider/.virtualenvs/Working/lib/python3.6/site-packages/django/core/handlers/exception.py", line 41, in inner
    response = get_response(request)
  File "/home/small-spider/.virtualenvs/Working/lib/python3.6/site-packages/django/core/handlers/base.py", line 187, in _get_response
    response = self.process_exception_by_middleware(e, request)
  File "/home/small-spider/.virtualenvs/Working/lib/python3.6/site-packages/django/core/handlers/base.py", line 185, in _get_response
    response = wrapped_callback(request, *callback_args, **callback_kwargs)
  File "/home/small-spider/.virtualenvs/Working/lib/python3.6/site-packages/django/views/generic/base.py", line 68, in view
    return self.dispatch(request, *args, **kwargs)
  File "/home/small-spider/.virtualenvs/Working/lib/python3.6/site-packages/django/views/generic/base.py", line 88, in dispatch
    return handler(request, *args, **kwargs)
  File "/home/small-spider/Documents/项目文件/线上版本/EPGN_INFO_4.17/apps/calculate/views.py", line 63, in post
    data_list = json.loads(body_str)["file_info"]
KeyError: 'file_info'
ERROR 2020-06-02 11:23:24,519 exception 135 Internal Server Error: /channelList/
Traceback (most recent call last):
  File "/home/small-spider/.virtualenvs/Working/lib/python3.6/site-packages/django/core/handlers/exception.py", line 41, in inner
    response = get_response(request)
  File "/home/small-spider/.virtualenvs/Working/lib/python3.6/site-packages/django/core/handlers/base.py", line 187, in _get_response
    response = self.process_exception_by_middleware(e, request)
  File "/home/small-spider/.virtualenvs/Working/lib/python3.6/site-packages/django/core/handlers/base.py", line 185, in _get_response
    response = wrapped_callback(request, *callback_args, **callback_kwargs)
  File "/home/small-spider/.virtualenvs/Working/lib/python3.6/site-packages/django/views/generic/base.py", line 68, in view
    return self.dispatch(request, *args, **kwargs)
  File "/home/small-spider/.virtualenvs/Working/lib/python3.6/site-packages/django/views/generic/base.py", line 88, in dispatch
    return handler(request, *args, **kwargs)
  File "/home/small-spider/Documents/项目文件/线上版本/EPGN_INFO_4.17/apps/calculate/views.py", line 63, in post
    data_list = json.loads(body_str)["file_info"]
KeyError: 'file_info'
ERROR 2020-06-02 11:25:07,203 exception 135 Internal Server Error: /channelList/
Traceback (most recent call last):
  File "/home/small-spider/.virtualenvs/Working/lib/python3.6/site-packages/django/core/handlers/exception.py", line 41, in inner
    response = get_response(request)
  File "/home/small-spider/.virtualenvs/Working/lib/python3.6/site-packages/django/core/handlers/base.py", line 187, in _get_response
    response = self.process_exception_by_middleware(e, request)
  File "/home/small-spider/.virtualenvs/Working/lib/python3.6/site-packages/django/core/handlers/base.py", line 185, in _get_response
    response = wrapped_callback(request, *callback_args, **callback_kwargs)
  File "/home/small-spider/.virtualenvs/Working/lib/python3.6/site-packages/django/views/generic/base.py", line 68, in view
    return self.dispatch(request, *args, **kwargs)
  File "/home/small-spider/.virtualenvs/Working/lib/python3.6/site-packages/django/views/generic/base.py", line 88, in dispatch
    return handler(request, *args, **kwargs)
  File "/home/small-spider/Documents/项目文件/线上版本/EPGN_INFO_4.17/apps/calculate/views.py", line 30, in put
    for file in data_list:
TypeError: 'NoneType' object is not iterable
ERROR 2020-06-02 13:03:53,537 exception 135 Internal Server Error: /user_calculate/
Traceback (most recent call last):
  File "/home/small-spider/.virtualenvs/Working/lib/python3.6/site-packages/django/core/handlers/exception.py", line 41, in inner
    response = get_response(request)
  File "/home/small-spider/.virtualenvs/Working/lib/python3.6/site-packages/django/core/handlers/base.py", line 187, in _get_response
    response = self.process_exception_by_middleware(e, request)
  File "/home/small-spider/.virtualenvs/Working/lib/python3.6/site-packages/django/core/handlers/base.py", line 185, in _get_response
    response = wrapped_callback(request, *callback_args, **callback_kwargs)
  File "/home/small-spider/Documents/项目文件/线上版本/EPGN_INFO_4.17/apps/calculate/views.py", line 342, in manual_report
    for children_file in body_json["children"]:  # 前端发送的数据通道不止一条
KeyError: 'children'
ERROR 2020-06-02 13:03:55,109 exception 135 Internal Server Error: /channelList/
Traceback (most recent call last):
  File "/home/small-spider/.virtualenvs/Working/lib/python3.6/site-packages/django/core/handlers/exception.py", line 41, in inner
    response = get_response(request)
  File "/home/small-spider/.virtualenvs/Working/lib/python3.6/site-packages/django/core/handlers/base.py", line 187, in _get_response
    response = self.process_exception_by_middleware(e, request)
  File "/home/small-spider/.virtualenvs/Working/lib/python3.6/site-packages/django/core/handlers/base.py", line 185, in _get_response
    response = wrapped_callback(request, *callback_args, **callback_kwargs)
  File "/home/small-spider/.virtualenvs/Working/lib/python3.6/site-packages/django/views/generic/base.py", line 68, in view
    return self.dispatch(request, *args, **kwargs)
  File "/home/small-spider/.virtualenvs/Working/lib/python3.6/site-packages/django/views/generic/base.py", line 88, in dispatch
    return handler(request, *args, **kwargs)
  File "/home/small-spider/Documents/项目文件/线上版本/EPGN_INFO_4.17/apps/calculate/views.py", line 63, in post
    data_list = json.loads(body_str)["file_info"]
KeyError: 'file_info'
ERROR 2020-06-02 13:12:04,617 exception 135 Internal Server Error: /user_calculate/
Traceback (most recent call last):
  File "/home/small-spider/.virtualenvs/Working/lib/python3.6/site-packages/django/core/handlers/exception.py", line 41, in inner
    response = get_response(request)
  File "/home/small-spider/.virtualenvs/Working/lib/python3.6/site-packages/django/core/handlers/base.py", line 187, in _get_response
    response = self.process_exception_by_middleware(e, request)
  File "/home/small-spider/.virtualenvs/Working/lib/python3.6/site-packages/django/core/handlers/base.py", line 185, in _get_response
    response = wrapped_callback(request, *callback_args, **callback_kwargs)
  File "/home/small-spider/Documents/项目文件/线上版本/EPGN_INFO_4.17/apps/calculate/views.py", line 342, in manual_report
    for children_file in body_json["children"]:  # 前端发送的数据通道不止一条
KeyError: 'children'
ERROR 2020-06-02 13:12:04,624 exception 135 Internal Server Error: /channelList/
Traceback (most recent call last):
  File "/home/small-spider/.virtualenvs/Working/lib/python3.6/site-packages/django/core/handlers/exception.py", line 41, in inner
    response = get_response(request)
  File "/home/small-spider/.virtualenvs/Working/lib/python3.6/site-packages/django/core/handlers/base.py", line 187, in _get_response
    response = self.process_exception_by_middleware(e, request)
  File "/home/small-spider/.virtualenvs/Working/lib/python3.6/site-packages/django/core/handlers/base.py", line 185, in _get_response
    response = wrapped_callback(request, *callback_args, **callback_kwargs)
  File "/home/small-spider/.virtualenvs/Working/lib/python3.6/site-packages/django/views/generic/base.py", line 68, in view
    return self.dispatch(request, *args, **kwargs)
  File "/home/small-spider/.virtualenvs/Working/lib/python3.6/site-packages/django/views/generic/base.py", line 88, in dispatch
    return handler(request, *args, **kwargs)
  File "/home/small-spider/Documents/项目文件/线上版本/EPGN_INFO_4.17/apps/calculate/views.py", line 63, in post
    data_list = json.loads(body_str)["file_info"]
KeyError: 'file_info'
ERROR 2020-06-02 13:12:06,597 exception 135 Internal Server Error: /channelList/
Traceback (most recent call last):
  File "/home/small-spider/.virtualenvs/Working/lib/python3.6/site-packages/django/core/handlers/exception.py", line 41, in inner
    response = get_response(request)
  File "/home/small-spider/.virtualenvs/Working/lib/python3.6/site-packages/django/core/handlers/base.py", line 187, in _get_response
    response = self.process_exception_by_middleware(e, request)
  File "/home/small-spider/.virtualenvs/Working/lib/python3.6/site-packages/django/core/handlers/base.py", line 185, in _get_response
    response = wrapped_callback(request, *callback_args, **callback_kwargs)
  File "/home/small-spider/.virtualenvs/Working/lib/python3.6/site-packages/django/views/generic/base.py", line 68, in view
    return self.dispatch(request, *args, **kwargs)
  File "/home/small-spider/.virtualenvs/Working/lib/python3.6/site-packages/django/views/generic/base.py", line 88, in dispatch
    return handler(request, *args, **kwargs)
  File "/home/small-spider/Documents/项目文件/线上版本/EPGN_INFO_4.17/apps/calculate/views.py", line 63, in post
    data_list = json.loads(body_str)["file_info"]
KeyError: 'file_info'
ERROR 2020-06-02 13:12:06,605 exception 135 Internal Server Error: /user_calculate/
Traceback (most recent call last):
  File "/home/small-spider/.virtualenvs/Working/lib/python3.6/site-packages/django/core/handlers/exception.py", line 41, in inner
    response = get_response(request)
  File "/home/small-spider/.virtualenvs/Working/lib/python3.6/site-packages/django/core/handlers/base.py", line 187, in _get_response
    response = self.process_exception_by_middleware(e, request)
  File "/home/small-spider/.virtualenvs/Working/lib/python3.6/site-packages/django/core/handlers/base.py", line 185, in _get_response
    response = wrapped_callback(request, *callback_args, **callback_kwargs)
  File "/home/small-spider/Documents/项目文件/线上版本/EPGN_INFO_4.17/apps/calculate/views.py", line 342, in manual_report
    for children_file in body_json["children"]:  # 前端发送的数据通道不止一条
KeyError: 'children'
ERROR 2020-06-02 13:13:04,681 exception 135 Internal Server Error: /channelList/
Traceback (most recent call last):
  File "/home/small-spider/.virtualenvs/Working/lib/python3.6/site-packages/django/core/handlers/exception.py", line 41, in inner
    response = get_response(request)
  File "/home/small-spider/.virtualenvs/Working/lib/python3.6/site-packages/django/core/handlers/base.py", line 187, in _get_response
    response = self.process_exception_by_middleware(e, request)
  File "/home/small-spider/.virtualenvs/Working/lib/python3.6/site-packages/django/core/handlers/base.py", line 185, in _get_response
    response = wrapped_callback(request, *callback_args, **callback_kwargs)
  File "/home/small-spider/.virtualenvs/Working/lib/python3.6/site-packages/django/views/generic/base.py", line 68, in view
    return self.dispatch(request, *args, **kwargs)
  File "/home/small-spider/.virtualenvs/Working/lib/python3.6/site-packages/django/views/generic/base.py", line 88, in dispatch
    return handler(request, *args, **kwargs)
  File "/home/small-spider/Documents/项目文件/线上版本/EPGN_INFO_4.17/apps/calculate/views.py", line 69, in post
    file_name = data["file_name"]
TypeError: string indices must be integers
ERROR 2020-06-02 13:13:04,684 exception 135 Internal Server Error: /user_calculate/
Traceback (most recent call last):
  File "/home/small-spider/.virtualenvs/Working/lib/python3.6/site-packages/django/core/handlers/exception.py", line 41, in inner
    response = get_response(request)
  File "/home/small-spider/.virtualenvs/Working/lib/python3.6/site-packages/django/core/handlers/base.py", line 187, in _get_response
    response = self.process_exception_by_middleware(e, request)
  File "/home/small-spider/.virtualenvs/Working/lib/python3.6/site-packages/django/core/handlers/base.py", line 185, in _get_response
    response = wrapped_callback(request, *callback_args, **callback_kwargs)
  File "/home/small-spider/Documents/项目文件/线上版本/EPGN_INFO_4.17/apps/calculate/views.py", line 342, in manual_report
    for children_file in body_json["children"]:  # 前端发送的数据通道不止一条
KeyError: 'children'
ERROR 2020-06-02 13:13:13,591 exception 135 Internal Server Error: /channelList/
Traceback (most recent call last):
  File "/home/small-spider/.virtualenvs/Working/lib/python3.6/site-packages/django/core/handlers/exception.py", line 41, in inner
    response = get_response(request)
  File "/home/small-spider/.virtualenvs/Working/lib/python3.6/site-packages/django/core/handlers/base.py", line 187, in _get_response
    response = self.process_exception_by_middleware(e, request)
  File "/home/small-spider/.virtualenvs/Working/lib/python3.6/site-packages/django/core/handlers/base.py", line 185, in _get_response
    response = wrapped_callback(request, *callback_args, **callback_kwargs)
  File "/home/small-spider/.virtualenvs/Working/lib/python3.6/site-packages/django/views/generic/base.py", line 68, in view
    return self.dispatch(request, *args, **kwargs)
  File "/home/small-spider/.virtualenvs/Working/lib/python3.6/site-packages/django/views/generic/base.py", line 88, in dispatch
    return handler(request, *args, **kwargs)
  File "/home/small-spider/Documents/项目文件/线上版本/EPGN_INFO_4.17/apps/calculate/views.py", line 69, in post
    file_name = data["file_name"]
TypeError: string indices must be integers
ERROR 2020-06-02 13:13:15,180 exception 135 Internal Server Error: /user_calculate/
Traceback (most recent call last):
  File "/home/small-spider/.virtualenvs/Working/lib/python3.6/site-packages/django/core/handlers/exception.py", line 41, in inner
    response = get_response(request)
  File "/home/small-spider/.virtualenvs/Working/lib/python3.6/site-packages/django/core/handlers/base.py", line 187, in _get_response
    response = self.process_exception_by_middleware(e, request)
  File "/home/small-spider/.virtualenvs/Working/lib/python3.6/site-packages/django/core/handlers/base.py", line 185, in _get_response
    response = wrapped_callback(request, *callback_args, **callback_kwargs)
  File "/home/small-spider/Documents/项目文件/线上版本/EPGN_INFO_4.17/apps/calculate/views.py", line 342, in manual_report
    for children_file in body_json["children"]:  # 前端发送的数据通道不止一条
KeyError: 'children'
ERROR 2020-06-02 13:13:34,174 exception 135 Internal Server Error: /user_calculate/
Traceback (most recent call last):
  File "/home/small-spider/.virtualenvs/Working/lib/python3.6/site-packages/django/core/handlers/exception.py", line 41, in inner
    response = get_response(request)
  File "/home/small-spider/.virtualenvs/Working/lib/python3.6/site-packages/django/core/handlers/base.py", line 187, in _get_response
    response = self.process_exception_by_middleware(e, request)
  File "/home/small-spider/.virtualenvs/Working/lib/python3.6/site-packages/django/core/handlers/base.py", line 185, in _get_response
    response = wrapped_callback(request, *callback_args, **callback_kwargs)
  File "/home/small-spider/Documents/项目文件/线上版本/EPGN_INFO_4.17/apps/calculate/views.py", line 342, in manual_report
    for children_file in body_json["children"]:  # 前端发送的数据通道不止一条
KeyError: 'children'
ERROR 2020-06-02 13:13:34,176 exception 135 Internal Server Error: /channelList/
Traceback (most recent call last):
  File "/home/small-spider/.virtualenvs/Working/lib/python3.6/site-packages/django/core/handlers/exception.py", line 41, in inner
    response = get_response(request)
  File "/home/small-spider/.virtualenvs/Working/lib/python3.6/site-packages/django/core/handlers/base.py", line 187, in _get_response
    response = self.process_exception_by_middleware(e, request)
  File "/home/small-spider/.virtualenvs/Working/lib/python3.6/site-packages/django/core/handlers/base.py", line 185, in _get_response
    response = wrapped_callback(request, *callback_args, **callback_kwargs)
  File "/home/small-spider/.virtualenvs/Working/lib/python3.6/site-packages/django/views/generic/base.py", line 68, in view
    return self.dispatch(request, *args, **kwargs)
  File "/home/small-spider/.virtualenvs/Working/lib/python3.6/site-packages/django/views/generic/base.py", line 88, in dispatch
    return handler(request, *args, **kwargs)
  File "/home/small-spider/Documents/项目文件/线上版本/EPGN_INFO_4.17/apps/calculate/views.py", line 69, in post
    file_name = data["file_name"]
TypeError: string indices must be integers
ERROR 2020-06-02 13:15:48,774 exception 135 Internal Server Error: /user_calculate/
Traceback (most recent call last):
  File "/home/small-spider/.virtualenvs/Working/lib/python3.6/site-packages/django/core/handlers/exception.py", line 41, in inner
    response = get_response(request)
  File "/home/small-spider/.virtualenvs/Working/lib/python3.6/site-packages/django/core/handlers/base.py", line 187, in _get_response
    response = self.process_exception_by_middleware(e, request)
  File "/home/small-spider/.virtualenvs/Working/lib/python3.6/site-packages/django/core/handlers/base.py", line 185, in _get_response
    response = wrapped_callback(request, *callback_args, **callback_kwargs)
  File "/home/small-spider/Documents/项目文件/线上版本/EPGN_INFO_4.17/apps/calculate/views.py", line 342, in manual_report
    for children_file in body_json["children"]:  # 前端发送的数据通道不止一条
KeyError: 'children'
ERROR 2020-06-02 13:17:07,254 exception 135 Internal Server Error: /user_calculate/
Traceback (most recent call last):
  File "/home/small-spider/.virtualenvs/Working/lib/python3.6/site-packages/django/core/handlers/exception.py", line 41, in inner
    response = get_response(request)
  File "/home/small-spider/.virtualenvs/Working/lib/python3.6/site-packages/django/core/handlers/base.py", line 187, in _get_response
    response = self.process_exception_by_middleware(e, request)
  File "/home/small-spider/.virtualenvs/Working/lib/python3.6/site-packages/django/core/handlers/base.py", line 185, in _get_response
    response = wrapped_callback(request, *callback_args, **callback_kwargs)
  File "/home/small-spider/Documents/项目文件/线上版本/EPGN_INFO_4.17/apps/calculate/views.py", line 342, in manual_report
    for children_file in body_json["children"]:  # 前端发送的数据通道不止一条
KeyError: 'children'
ERROR 2020-06-02 13:17:07,256 exception 135 Internal Server Error: /channelList/
Traceback (most recent call last):
  File "/home/small-spider/.virtualenvs/Working/lib/python3.6/site-packages/django/core/handlers/exception.py", line 41, in inner
    response = get_response(request)
  File "/home/small-spider/.virtualenvs/Working/lib/python3.6/site-packages/django/core/handlers/base.py", line 187, in _get_response
    response = self.process_exception_by_middleware(e, request)
  File "/home/small-spider/.virtualenvs/Working/lib/python3.6/site-packages/django/core/handlers/base.py", line 185, in _get_response
    response = wrapped_callback(request, *callback_args, **callback_kwargs)
  File "/home/small-spider/.virtualenvs/Working/lib/python3.6/site-packages/django/views/generic/base.py", line 68, in view
    return self.dispatch(request, *args, **kwargs)
  File "/home/small-spider/.virtualenvs/Working/lib/python3.6/site-packages/django/views/generic/base.py", line 88, in dispatch
    return handler(request, *args, **kwargs)
  File "/home/small-spider/Documents/项目文件/线上版本/EPGN_INFO_4.17/apps/calculate/views.py", line 69, in post
    file_name = data["file_name"]
TypeError: string indices must be integers
ERROR 2020-06-02 13:31:57,907 exception 135 Internal Server Error: /channelList/
Traceback (most recent call last):
  File "/home/small-spider/.virtualenvs/Working/lib/python3.6/site-packages/django/core/handlers/exception.py", line 41, in inner
    response = get_response(request)
  File "/home/small-spider/.virtualenvs/Working/lib/python3.6/site-packages/django/core/handlers/base.py", line 187, in _get_response
    response = self.process_exception_by_middleware(e, request)
  File "/home/small-spider/.virtualenvs/Working/lib/python3.6/site-packages/django/core/handlers/base.py", line 185, in _get_response
    response = wrapped_callback(request, *callback_args, **callback_kwargs)
  File "/home/small-spider/.virtualenvs/Working/lib/python3.6/site-packages/django/views/generic/base.py", line 68, in view
    return self.dispatch(request, *args, **kwargs)
  File "/home/small-spider/.virtualenvs/Working/lib/python3.6/site-packages/django/views/generic/base.py", line 88, in dispatch
    return handler(request, *args, **kwargs)
  File "/home/small-spider/Documents/项目文件/线上版本/EPGN_INFO_4.17/apps/calculate/views.py", line 69, in post
    file_name = data["file_name"]
TypeError: string indices must be integers
ERROR 2020-06-02 13:31:59,496 exception 135 Internal Server Error: /user_calculate/
Traceback (most recent call last):
  File "/home/small-spider/.virtualenvs/Working/lib/python3.6/site-packages/django/core/handlers/exception.py", line 41, in inner
    response = get_response(request)
  File "/home/small-spider/.virtualenvs/Working/lib/python3.6/site-packages/django/core/handlers/base.py", line 187, in _get_response
    response = self.process_exception_by_middleware(e, request)
  File "/home/small-spider/.virtualenvs/Working/lib/python3.6/site-packages/django/core/handlers/base.py", line 185, in _get_response
    response = wrapped_callback(request, *callback_args, **callback_kwargs)
  File "/home/small-spider/Documents/项目文件/线上版本/EPGN_INFO_4.17/apps/calculate/views.py", line 342, in manual_report
    for children_file in body_json["children"]:  # 前端发送的数据通道不止一条
KeyError: 'children'
ERROR 2020-06-02 15:55:13,668 exception 135 Internal Server Error: /channelList/
Traceback (most recent call last):
  File "/home/small-spider/.virtualenvs/Working/lib/python3.6/site-packages/django/core/handlers/exception.py", line 41, in inner
    response = get_response(request)
  File "/home/small-spider/.virtualenvs/Working/lib/python3.6/site-packages/django/core/handlers/base.py", line 187, in _get_response
    response = self.process_exception_by_middleware(e, request)
  File "/home/small-spider/.virtualenvs/Working/lib/python3.6/site-packages/django/core/handlers/base.py", line 185, in _get_response
    response = wrapped_callback(request, *callback_args, **callback_kwargs)
  File "/home/small-spider/.virtualenvs/Working/lib/python3.6/site-packages/django/views/generic/base.py", line 68, in view
    return self.dispatch(request, *args, **kwargs)
  File "/home/small-spider/.virtualenvs/Working/lib/python3.6/site-packages/django/views/generic/base.py", line 88, in dispatch
    return handler(request, *args, **kwargs)
  File "/home/small-spider/Documents/项目文件/线上版本/EPGN_INFO_4.17/apps/calculate/views.py", line 69, in post
    file_name = data["file_name"]
TypeError: string indices must be integers
ERROR 2020-06-02 15:56:37,505 exception 135 Internal Server Error: /channelList/
Traceback (most recent call last):
  File "/home/small-spider/.virtualenvs/Working/lib/python3.6/site-packages/django/core/handlers/exception.py", line 41, in inner
    response = get_response(request)
  File "/home/small-spider/.virtualenvs/Working/lib/python3.6/site-packages/django/core/handlers/base.py", line 187, in _get_response
    response = self.process_exception_by_middleware(e, request)
  File "/home/small-spider/.virtualenvs/Working/lib/python3.6/site-packages/django/core/handlers/base.py", line 185, in _get_response
    response = wrapped_callback(request, *callback_args, **callback_kwargs)
  File "/home/small-spider/.virtualenvs/Working/lib/python3.6/site-packages/django/views/generic/base.py", line 68, in view
    return self.dispatch(request, *args, **kwargs)
  File "/home/small-spider/.virtualenvs/Working/lib/python3.6/site-packages/django/views/generic/base.py", line 88, in dispatch
    return handler(request, *args, **kwargs)
  File "/home/small-spider/Documents/项目文件/线上版本/EPGN_INFO_4.17/apps/calculate/views.py", line 69, in post
    file_name = data["file_name"]
TypeError: string indices must be integers
ERROR 2020-06-02 15:58:38,859 exception 135 Internal Server Error: /channelList/
Traceback (most recent call last):
  File "/home/small-spider/.virtualenvs/Working/lib/python3.6/site-packages/django/core/handlers/exception.py", line 41, in inner
    response = get_response(request)
  File "/home/small-spider/.virtualenvs/Working/lib/python3.6/site-packages/django/core/handlers/base.py", line 187, in _get_response
    response = self.process_exception_by_middleware(e, request)
  File "/home/small-spider/.virtualenvs/Working/lib/python3.6/site-packages/django/core/handlers/base.py", line 185, in _get_response
    response = wrapped_callback(request, *callback_args, **callback_kwargs)
  File "/home/small-spider/.virtualenvs/Working/lib/python3.6/site-packages/django/views/generic/base.py", line 68, in view
    return self.dispatch(request, *args, **kwargs)
  File "/home/small-spider/.virtualenvs/Working/lib/python3.6/site-packages/django/views/generic/base.py", line 88, in dispatch
    return handler(request, *args, **kwargs)
  File "/home/small-spider/Documents/项目文件/线上版本/EPGN_INFO_4.17/apps/calculate/views.py", line 69, in post
    file_name = data["file_name"]
TypeError: string indices must be integers
ERROR 2020-06-02 16:00:51,955 exception 135 Internal Server Error: /channelList/
Traceback (most recent call last):
  File "/home/small-spider/.virtualenvs/Working/lib/python3.6/site-packages/django/core/handlers/exception.py", line 41, in inner
    response = get_response(request)
  File "/home/small-spider/.virtualenvs/Working/lib/python3.6/site-packages/django/core/handlers/base.py", line 187, in _get_response
    response = self.process_exception_by_middleware(e, request)
  File "/home/small-spider/.virtualenvs/Working/lib/python3.6/site-packages/django/core/handlers/base.py", line 185, in _get_response
    response = wrapped_callback(request, *callback_args, **callback_kwargs)
  File "/home/small-spider/.virtualenvs/Working/lib/python3.6/site-packages/django/views/generic/base.py", line 68, in view
    return self.dispatch(request, *args, **kwargs)
  File "/home/small-spider/.virtualenvs/Working/lib/python3.6/site-packages/django/views/generic/base.py", line 88, in dispatch
    return handler(request, *args, **kwargs)
  File "/home/small-spider/Documents/项目文件/线上版本/EPGN_INFO_4.17/apps/calculate/views.py", line 69, in post
    file_name = data["file_name"]
TypeError: string indices must be integers
ERROR 2020-06-02 16:01:38,249 exception 135 Internal Server Error: /channelList/
Traceback (most recent call last):
  File "/home/small-spider/.virtualenvs/Working/lib/python3.6/site-packages/django/core/handlers/exception.py", line 41, in inner
    response = get_response(request)
  File "/home/small-spider/.virtualenvs/Working/lib/python3.6/site-packages/django/core/handlers/base.py", line 187, in _get_response
    response = self.process_exception_by_middleware(e, request)
  File "/home/small-spider/.virtualenvs/Working/lib/python3.6/site-packages/django/core/handlers/base.py", line 185, in _get_response
    response = wrapped_callback(request, *callback_args, **callback_kwargs)
  File "/home/small-spider/.virtualenvs/Working/lib/python3.6/site-packages/django/views/generic/base.py", line 68, in view
    return self.dispatch(request, *args, **kwargs)
  File "/home/small-spider/.virtualenvs/Working/lib/python3.6/site-packages/django/views/generic/base.py", line 88, in dispatch
    return handler(request, *args, **kwargs)
  File "/home/small-spider/Documents/项目文件/线上版本/EPGN_INFO_4.17/apps/calculate/views.py", line 69, in post
    file_name = data["file_name"]
TypeError: string indices must be integers
ERROR 2020-06-02 16:02:22,059 exception 135 Internal Server Error: /channelList/
Traceback (most recent call last):
  File "/home/small-spider/.virtualenvs/Working/lib/python3.6/site-packages/django/core/handlers/exception.py", line 41, in inner
    response = get_response(request)
  File "/home/small-spider/.virtualenvs/Working/lib/python3.6/site-packages/django/core/handlers/base.py", line 187, in _get_response
    response = self.process_exception_by_middleware(e, request)
  File "/home/small-spider/.virtualenvs/Working/lib/python3.6/site-packages/django/core/handlers/base.py", line 185, in _get_response
    response = wrapped_callback(request, *callback_args, **callback_kwargs)
  File "/home/small-spider/.virtualenvs/Working/lib/python3.6/site-packages/django/views/generic/base.py", line 68, in view
    return self.dispatch(request, *args, **kwargs)
  File "/home/small-spider/.virtualenvs/Working/lib/python3.6/site-packages/django/views/generic/base.py", line 88, in dispatch
    return handler(request, *args, **kwargs)
  File "/home/small-spider/Documents/项目文件/线上版本/EPGN_INFO_4.17/apps/calculate/views.py", line 69, in post
    file_name = data["file_name"]
TypeError: string indices must be integers
ERROR 2020-06-02 16:02:38,089 exception 135 Internal Server Error: /channelList/
Traceback (most recent call last):
  File "/home/small-spider/.virtualenvs/Working/lib/python3.6/site-packages/django/core/handlers/exception.py", line 41, in inner
    response = get_response(request)
  File "/home/small-spider/.virtualenvs/Working/lib/python3.6/site-packages/django/core/handlers/base.py", line 187, in _get_response
    response = self.process_exception_by_middleware(e, request)
  File "/home/small-spider/.virtualenvs/Working/lib/python3.6/site-packages/django/core/handlers/base.py", line 185, in _get_response
    response = wrapped_callback(request, *callback_args, **callback_kwargs)
  File "/home/small-spider/.virtualenvs/Working/lib/python3.6/site-packages/django/views/generic/base.py", line 68, in view
    return self.dispatch(request, *args, **kwargs)
  File "/home/small-spider/.virtualenvs/Working/lib/python3.6/site-packages/django/views/generic/base.py", line 88, in dispatch
    return handler(request, *args, **kwargs)
  File "/home/small-spider/Documents/项目文件/线上版本/EPGN_INFO_4.17/apps/calculate/views.py", line 69, in post
    file_name = data["file_name"]
TypeError: string indices must be integers
ERROR 2020-06-02 16:04:40,290 exception 135 Internal Server Error: /channelList/
Traceback (most recent call last):
  File "/home/small-spider/.virtualenvs/Working/lib/python3.6/site-packages/django/core/handlers/exception.py", line 41, in inner
    response = get_response(request)
  File "/home/small-spider/.virtualenvs/Working/lib/python3.6/site-packages/django/core/handlers/base.py", line 187, in _get_response
    response = self.process_exception_by_middleware(e, request)
  File "/home/small-spider/.virtualenvs/Working/lib/python3.6/site-packages/django/core/handlers/base.py", line 185, in _get_response
    response = wrapped_callback(request, *callback_args, **callback_kwargs)
  File "/home/small-spider/.virtualenvs/Working/lib/python3.6/site-packages/django/views/generic/base.py", line 68, in view
    return self.dispatch(request, *args, **kwargs)
  File "/home/small-spider/.virtualenvs/Working/lib/python3.6/site-packages/django/views/generic/base.py", line 88, in dispatch
    return handler(request, *args, **kwargs)
  File "/home/small-spider/Documents/项目文件/线上版本/EPGN_INFO_4.17/apps/calculate/views.py", line 69, in post
    file_name = data["file_name"]
TypeError: string indices must be integers
ERROR 2020-06-03 10:10:31,549 exception 135 Internal Server Error: /channelList/
Traceback (most recent call last):
  File "/home/small-spider/.virtualenvs/Working/lib/python3.6/site-packages/django/core/handlers/exception.py", line 41, in inner
    response = get_response(request)
  File "/home/small-spider/.virtualenvs/Working/lib/python3.6/site-packages/django/core/handlers/base.py", line 187, in _get_response
    response = self.process_exception_by_middleware(e, request)
  File "/home/small-spider/.virtualenvs/Working/lib/python3.6/site-packages/django/core/handlers/base.py", line 185, in _get_response
    response = wrapped_callback(request, *callback_args, **callback_kwargs)
  File "/home/small-spider/.virtualenvs/Working/lib/python3.6/site-packages/django/views/generic/base.py", line 68, in view
    return self.dispatch(request, *args, **kwargs)
  File "/home/small-spider/.virtualenvs/Working/lib/python3.6/site-packages/django/views/generic/base.py", line 88, in dispatch
    return handler(request, *args, **kwargs)
  File "/home/small-spider/Documents/项目文件/线上版本/EPGN_INFO_4.17/apps/calculate/views.py", line 69, in post
    file_name = data["file_name"]
TypeError: string indices must be integers
ERROR 2020-06-03 10:20:40,375 exception 135 Internal Server Error: /channelList/
Traceback (most recent call last):
  File "/home/small-spider/.virtualenvs/Working/lib/python3.6/site-packages/django/core/handlers/exception.py", line 41, in inner
    response = get_response(request)
  File "/home/small-spider/.virtualenvs/Working/lib/python3.6/site-packages/django/core/handlers/base.py", line 187, in _get_response
    response = self.process_exception_by_middleware(e, request)
  File "/home/small-spider/.virtualenvs/Working/lib/python3.6/site-packages/django/core/handlers/base.py", line 185, in _get_response
    response = wrapped_callback(request, *callback_args, **callback_kwargs)
  File "/home/small-spider/.virtualenvs/Working/lib/python3.6/site-packages/django/views/generic/base.py", line 68, in view
    return self.dispatch(request, *args, **kwargs)
  File "/home/small-spider/.virtualenvs/Working/lib/python3.6/site-packages/django/views/generic/base.py", line 88, in dispatch
    return handler(request, *args, **kwargs)
  File "/home/small-spider/Documents/项目文件/线上版本/EPGN_INFO_4.17/apps/calculate/views.py", line 69, in post
    file_name = data["file_name"]
TypeError: string indices must be integers
ERROR 2020-06-03 10:20:40,377 exception 135 Internal Server Error: /user_calculate/
Traceback (most recent call last):
  File "/home/small-spider/.virtualenvs/Working/lib/python3.6/site-packages/django/core/handlers/exception.py", line 41, in inner
    response = get_response(request)
  File "/home/small-spider/.virtualenvs/Working/lib/python3.6/site-packages/django/core/handlers/base.py", line 187, in _get_response
    response = self.process_exception_by_middleware(e, request)
  File "/home/small-spider/.virtualenvs/Working/lib/python3.6/site-packages/django/core/handlers/base.py", line 185, in _get_response
    response = wrapped_callback(request, *callback_args, **callback_kwargs)
  File "/home/small-spider/Documents/项目文件/线上版本/EPGN_INFO_4.17/apps/calculate/views.py", line 342, in manual_report
    for children_file in body_json["children"]:  # 前端发送的数据通道不止一条
KeyError: 'children'
ERROR 2020-06-03 10:23:37,588 exception 135 Internal Server Error: /channelList/
Traceback (most recent call last):
  File "/home/small-spider/.virtualenvs/Working/lib/python3.6/site-packages/django/core/handlers/exception.py", line 41, in inner
    response = get_response(request)
  File "/home/small-spider/.virtualenvs/Working/lib/python3.6/site-packages/django/core/handlers/base.py", line 187, in _get_response
    response = self.process_exception_by_middleware(e, request)
  File "/home/small-spider/.virtualenvs/Working/lib/python3.6/site-packages/django/core/handlers/base.py", line 185, in _get_response
    response = wrapped_callback(request, *callback_args, **callback_kwargs)
  File "/home/small-spider/.virtualenvs/Working/lib/python3.6/site-packages/django/views/generic/base.py", line 68, in view
    return self.dispatch(request, *args, **kwargs)
  File "/home/small-spider/.virtualenvs/Working/lib/python3.6/site-packages/django/views/generic/base.py", line 88, in dispatch
    return handler(request, *args, **kwargs)
  File "/home/small-spider/Documents/项目文件/线上版本/EPGN_INFO_4.17/apps/calculate/views.py", line 69, in post
    file_name = data["file_name"]
TypeError: string indices must be integers
ERROR 2020-06-03 10:23:37,615 exception 135 Internal Server Error: /user_calculate/
Traceback (most recent call last):
  File "/home/small-spider/.virtualenvs/Working/lib/python3.6/site-packages/django/core/handlers/exception.py", line 41, in inner
    response = get_response(request)
  File "/home/small-spider/.virtualenvs/Working/lib/python3.6/site-packages/django/core/handlers/base.py", line 187, in _get_response
    response = self.process_exception_by_middleware(e, request)
  File "/home/small-spider/.virtualenvs/Working/lib/python3.6/site-packages/django/core/handlers/base.py", line 185, in _get_response
    response = wrapped_callback(request, *callback_args, **callback_kwargs)
  File "/home/small-spider/Documents/项目文件/线上版本/EPGN_INFO_4.17/apps/calculate/views.py", line 342, in manual_report
    print(body_json["children"])
KeyError: 'children'
ERROR 2020-06-03 10:25:04,343 exception 135 Internal Server Error: /user_calculate/
Traceback (most recent call last):
  File "/home/small-spider/.virtualenvs/Working/lib/python3.6/site-packages/django/core/handlers/exception.py", line 41, in inner
    response = get_response(request)
  File "/home/small-spider/.virtualenvs/Working/lib/python3.6/site-packages/django/core/handlers/base.py", line 187, in _get_response
    response = self.process_exception_by_middleware(e, request)
  File "/home/small-spider/.virtualenvs/Working/lib/python3.6/site-packages/django/core/handlers/base.py", line 185, in _get_response
    response = wrapped_callback(request, *callback_args, **callback_kwargs)
  File "/home/small-spider/Documents/项目文件/线上版本/EPGN_INFO_4.17/apps/calculate/views.py", line 343, in manual_report
    print(body_json["children"])
KeyError: 'children'
ERROR 2020-06-03 10:25:04,354 exception 135 Internal Server Error: /channelList/
Traceback (most recent call last):
  File "/home/small-spider/.virtualenvs/Working/lib/python3.6/site-packages/django/core/handlers/exception.py", line 41, in inner
    response = get_response(request)
  File "/home/small-spider/.virtualenvs/Working/lib/python3.6/site-packages/django/core/handlers/base.py", line 187, in _get_response
    response = self.process_exception_by_middleware(e, request)
  File "/home/small-spider/.virtualenvs/Working/lib/python3.6/site-packages/django/core/handlers/base.py", line 185, in _get_response
    response = wrapped_callback(request, *callback_args, **callback_kwargs)
  File "/home/small-spider/.virtualenvs/Working/lib/python3.6/site-packages/django/views/generic/base.py", line 68, in view
    return self.dispatch(request, *args, **kwargs)
  File "/home/small-spider/.virtualenvs/Working/lib/python3.6/site-packages/django/views/generic/base.py", line 88, in dispatch
    return handler(request, *args, **kwargs)
  File "/home/small-spider/Documents/项目文件/线上版本/EPGN_INFO_4.17/apps/calculate/views.py", line 69, in post
    file_name = data["file_name"]
TypeError: string indices must be integers
ERROR 2020-06-03 10:27:18,845 exception 135 Internal Server Error: /user_calculate/
Traceback (most recent call last):
  File "/home/small-spider/.virtualenvs/Working/lib/python3.6/site-packages/django/core/handlers/exception.py", line 41, in inner
    response = get_response(request)
  File "/home/small-spider/.virtualenvs/Working/lib/python3.6/site-packages/django/core/handlers/base.py", line 187, in _get_response
    response = self.process_exception_by_middleware(e, request)
  File "/home/small-spider/.virtualenvs/Working/lib/python3.6/site-packages/django/core/handlers/base.py", line 185, in _get_response
    response = wrapped_callback(request, *callback_args, **callback_kwargs)
  File "/home/small-spider/Documents/项目文件/线上版本/EPGN_INFO_4.17/apps/calculate/views.py", line 343, in manual_report
    print(body_json["children"])
KeyError: 'children'
ERROR 2020-06-03 10:27:18,844 exception 135 Internal Server Error: /channelList/
Traceback (most recent call last):
  File "/home/small-spider/.virtualenvs/Working/lib/python3.6/site-packages/django/core/handlers/exception.py", line 41, in inner
    response = get_response(request)
  File "/home/small-spider/.virtualenvs/Working/lib/python3.6/site-packages/django/core/handlers/base.py", line 187, in _get_response
    response = self.process_exception_by_middleware(e, request)
  File "/home/small-spider/.virtualenvs/Working/lib/python3.6/site-packages/django/core/handlers/base.py", line 185, in _get_response
    response = wrapped_callback(request, *callback_args, **callback_kwargs)
  File "/home/small-spider/.virtualenvs/Working/lib/python3.6/site-packages/django/views/generic/base.py", line 68, in view
    return self.dispatch(request, *args, **kwargs)
  File "/home/small-spider/.virtualenvs/Working/lib/python3.6/site-packages/django/views/generic/base.py", line 88, in dispatch
    return handler(request, *args, **kwargs)
  File "/home/small-spider/Documents/项目文件/线上版本/EPGN_INFO_4.17/apps/calculate/views.py", line 69, in post
    file_name = data["file_name"]
TypeError: string indices must be integers
WARNING 2020-06-03 10:31:13,158 base 152 Not Found: /epgn_front_end/login_2.html
WARNING 2020-06-03 10:31:14,984 base 152 Not Found: /epgn_front_end/login_2.html
WARNING 2020-06-03 10:31:15,731 base 152 Not Found: /epgn_front_end/login_2.html
WARNING 2020-06-03 10:31:16,667 base 152 Not Found: /epgn_front_end/login_2.html
WARNING 2020-06-03 10:31:21,787 base 152 Not Found: /epgn_front_end/login_2.html
WARNING 2020-06-03 10:31:22,419 base 152 Not Found: /epgn_front_end/login_2.html
WARNING 2020-06-03 10:31:22,603 base 152 Not Found: /epgn_front_end/login_2.html
WARNING 2020-06-03 10:31:22,762 base 152 Not Found: /epgn_front_end/login_2.html
WARNING 2020-06-03 10:31:22,931 base 152 Not Found: /epgn_front_end/login_2.html
WARNING 2020-06-03 10:31:23,091 base 152 Not Found: /epgn_front_end/login_2.html
WARNING 2020-06-03 10:31:23,257 base 152 Not Found: /epgn_front_end/login_2.html
WARNING 2020-06-03 10:31:23,410 base 152 Not Found: /epgn_front_end/login_2.html
WARNING 2020-06-03 10:31:23,571 base 152 Not Found: /epgn_front_end/login_2.html
WARNING 2020-06-03 10:31:23,757 base 152 Not Found: /epgn_front_end/login_2.html
ERROR 2020-06-03 10:32:31,401 exception 135 Internal Server Error: /user_calculate/
Traceback (most recent call last):
  File "/home/small-spider/.virtualenvs/Working/lib/python3.6/site-packages/django/core/handlers/exception.py", line 41, in inner
    response = get_response(request)
  File "/home/small-spider/.virtualenvs/Working/lib/python3.6/site-packages/django/core/handlers/base.py", line 187, in _get_response
    response = self.process_exception_by_middleware(e, request)
  File "/home/small-spider/.virtualenvs/Working/lib/python3.6/site-packages/django/core/handlers/base.py", line 185, in _get_response
    response = wrapped_callback(request, *callback_args, **callback_kwargs)
  File "/home/small-spider/Documents/项目文件/线上版本/EPGN_INFO_4.17/apps/calculate/views.py", line 343, in manual_report
    print(body_json["children"])
TypeError: list indices must be integers or slices, not str
ERROR 2020-06-03 10:32:31,404 exception 135 Internal Server Error: /channelList/
Traceback (most recent call last):
  File "/home/small-spider/.virtualenvs/Working/lib/python3.6/site-packages/django/core/handlers/exception.py", line 41, in inner
    response = get_response(request)
  File "/home/small-spider/.virtualenvs/Working/lib/python3.6/site-packages/django/core/handlers/base.py", line 187, in _get_response
    response = self.process_exception_by_middleware(e, request)
  File "/home/small-spider/.virtualenvs/Working/lib/python3.6/site-packages/django/core/handlers/base.py", line 185, in _get_response
    response = wrapped_callback(request, *callback_args, **callback_kwargs)
  File "/home/small-spider/.virtualenvs/Working/lib/python3.6/site-packages/django/views/generic/base.py", line 68, in view
    return self.dispatch(request, *args, **kwargs)
  File "/home/small-spider/.virtualenvs/Working/lib/python3.6/site-packages/django/views/generic/base.py", line 88, in dispatch
    return handler(request, *args, **kwargs)
  File "/home/small-spider/Documents/项目文件/线上版本/EPGN_INFO_4.17/apps/calculate/views.py", line 69, in post
    file_name = data["file_name"]
TypeError: string indices must be integers
ERROR 2020-06-03 10:33:42,119 exception 135 Internal Server Error: /channelList/
Traceback (most recent call last):
  File "/home/small-spider/.virtualenvs/Working/lib/python3.6/site-packages/django/core/handlers/exception.py", line 41, in inner
    response = get_response(request)
  File "/home/small-spider/.virtualenvs/Working/lib/python3.6/site-packages/django/core/handlers/base.py", line 187, in _get_response
    response = self.process_exception_by_middleware(e, request)
  File "/home/small-spider/.virtualenvs/Working/lib/python3.6/site-packages/django/core/handlers/base.py", line 185, in _get_response
    response = wrapped_callback(request, *callback_args, **callback_kwargs)
  File "/home/small-spider/.virtualenvs/Working/lib/python3.6/site-packages/django/views/generic/base.py", line 68, in view
    return self.dispatch(request, *args, **kwargs)
  File "/home/small-spider/.virtualenvs/Working/lib/python3.6/site-packages/django/views/generic/base.py", line 88, in dispatch
    return handler(request, *args, **kwargs)
  File "/home/small-spider/Documents/项目文件/线上版本/EPGN_INFO_4.17/apps/calculate/views.py", line 69, in post
    file_name = data["file_name"]
TypeError: string indices must be integers
ERROR 2020-06-03 10:33:42,121 exception 135 Internal Server Error: /user_calculate/
Traceback (most recent call last):
  File "/home/small-spider/.virtualenvs/Working/lib/python3.6/site-packages/django/core/handlers/exception.py", line 41, in inner
    response = get_response(request)
  File "/home/small-spider/.virtualenvs/Working/lib/python3.6/site-packages/django/core/handlers/base.py", line 187, in _get_response
    response = self.process_exception_by_middleware(e, request)
  File "/home/small-spider/.virtualenvs/Working/lib/python3.6/site-packages/django/core/handlers/base.py", line 185, in _get_response
    response = wrapped_callback(request, *callback_args, **callback_kwargs)
  File "/home/small-spider/Documents/项目文件/线上版本/EPGN_INFO_4.17/apps/calculate/views.py", line 343, in manual_report
    print(body_json["children"])
TypeError: list indices must be integers or slices, not str
ERROR 2020-06-03 10:34:07,085 exception 135 Internal Server Error: /channelList/
Traceback (most recent call last):
  File "/home/small-spider/.virtualenvs/Working/lib/python3.6/site-packages/django/core/handlers/exception.py", line 41, in inner
    response = get_response(request)
  File "/home/small-spider/.virtualenvs/Working/lib/python3.6/site-packages/django/core/handlers/base.py", line 187, in _get_response
    response = self.process_exception_by_middleware(e, request)
  File "/home/small-spider/.virtualenvs/Working/lib/python3.6/site-packages/django/core/handlers/base.py", line 185, in _get_response
    response = wrapped_callback(request, *callback_args, **callback_kwargs)
  File "/home/small-spider/.virtualenvs/Working/lib/python3.6/site-packages/django/views/generic/base.py", line 68, in view
    return self.dispatch(request, *args, **kwargs)
  File "/home/small-spider/.virtualenvs/Working/lib/python3.6/site-packages/django/views/generic/base.py", line 88, in dispatch
    return handler(request, *args, **kwargs)
  File "/home/small-spider/Documents/项目文件/线上版本/EPGN_INFO_4.17/apps/calculate/views.py", line 69, in post
    file_name = data["file_name"]
TypeError: string indices must be integers
ERROR 2020-06-03 10:34:07,726 exception 135 Internal Server Error: /user_calculate/
Traceback (most recent call last):
  File "/home/small-spider/.virtualenvs/Working/lib/python3.6/site-packages/django/core/handlers/exception.py", line 41, in inner
    response = get_response(request)
  File "/home/small-spider/.virtualenvs/Working/lib/python3.6/site-packages/django/core/handlers/base.py", line 187, in _get_response
    response = self.process_exception_by_middleware(e, request)
  File "/home/small-spider/.virtualenvs/Working/lib/python3.6/site-packages/django/core/handlers/base.py", line 185, in _get_response
    response = wrapped_callback(request, *callback_args, **callback_kwargs)
  File "/home/small-spider/Documents/项目文件/线上版本/EPGN_INFO_4.17/apps/calculate/views.py", line 382, in manual_report
    items = ParseTask(data, rpm_type).run()
  File "./scripts/process_gecent.py", line 91, in run
    self.parse_file_info()
  File "./scripts/process_gecent.py", line 48, in parse_file_info
    list(channel_file_list.values()).index(channel["title"])]
ValueError: 'data_vornlinks' is not in list
ERROR 2020-06-03 10:36:14,348 exception 135 Internal Server Error: /channelList/
Traceback (most recent call last):
  File "/home/small-spider/.virtualenvs/Working/lib/python3.6/site-packages/django/core/handlers/exception.py", line 41, in inner
    response = get_response(request)
  File "/home/small-spider/.virtualenvs/Working/lib/python3.6/site-packages/django/core/handlers/base.py", line 187, in _get_response
    response = self.process_exception_by_middleware(e, request)
  File "/home/small-spider/.virtualenvs/Working/lib/python3.6/site-packages/django/core/handlers/base.py", line 185, in _get_response
    response = wrapped_callback(request, *callback_args, **callback_kwargs)
  File "/home/small-spider/.virtualenvs/Working/lib/python3.6/site-packages/django/views/generic/base.py", line 68, in view
    return self.dispatch(request, *args, **kwargs)
  File "/home/small-spider/.virtualenvs/Working/lib/python3.6/site-packages/django/views/generic/base.py", line 88, in dispatch
    return handler(request, *args, **kwargs)
  File "/home/small-spider/Documents/项目文件/线上版本/EPGN_INFO_4.17/apps/calculate/views.py", line 69, in post
    file_name = data["file_name"]
TypeError: string indices must be integers
ERROR 2020-06-03 10:36:14,867 exception 135 Internal Server Error: /user_calculate/
Traceback (most recent call last):
  File "/home/small-spider/.virtualenvs/Working/lib/python3.6/site-packages/django/core/handlers/exception.py", line 41, in inner
    response = get_response(request)
  File "/home/small-spider/.virtualenvs/Working/lib/python3.6/site-packages/django/core/handlers/base.py", line 187, in _get_response
    response = self.process_exception_by_middleware(e, request)
  File "/home/small-spider/.virtualenvs/Working/lib/python3.6/site-packages/django/core/handlers/base.py", line 185, in _get_response
    response = wrapped_callback(request, *callback_args, **callback_kwargs)
  File "/home/small-spider/Documents/项目文件/线上版本/EPGN_INFO_4.17/apps/calculate/views.py", line 382, in manual_report
    items = ParseTask(data, rpm_type).run()
  File "./scripts/process_gecent.py", line 91, in run
    self.parse_file_info()
  File "./scripts/process_gecent.py", line 48, in parse_file_info
    channel_data_key = list(channel_file_list.keys())[list(channel_file_list.values()).index(channel["title"])]
ValueError: 'data_vornlinks' is not in list
ERROR 2020-06-03 10:46:15,329 exception 135 Internal Server Error: /channelList/
Traceback (most recent call last):
  File "/home/small-spider/.virtualenvs/Working/lib/python3.6/site-packages/django/core/handlers/exception.py", line 41, in inner
    response = get_response(request)
  File "/home/small-spider/.virtualenvs/Working/lib/python3.6/site-packages/django/core/handlers/base.py", line 187, in _get_response
    response = self.process_exception_by_middleware(e, request)
  File "/home/small-spider/.virtualenvs/Working/lib/python3.6/site-packages/django/core/handlers/base.py", line 185, in _get_response
    response = wrapped_callback(request, *callback_args, **callback_kwargs)
  File "/home/small-spider/.virtualenvs/Working/lib/python3.6/site-packages/django/views/generic/base.py", line 68, in view
    return self.dispatch(request, *args, **kwargs)
  File "/home/small-spider/.virtualenvs/Working/lib/python3.6/site-packages/django/views/generic/base.py", line 88, in dispatch
    return handler(request, *args, **kwargs)
  File "/home/small-spider/Documents/项目文件/线上版本/EPGN_INFO_4.17/apps/calculate/views.py", line 71, in post
    file_name = data["file_name"]
TypeError: string indices must be integers
ERROR 2020-06-03 10:46:30,694 exception 135 Internal Server Error: /channelList/
Traceback (most recent call last):
  File "/home/small-spider/.virtualenvs/Working/lib/python3.6/site-packages/django/core/handlers/exception.py", line 41, in inner
    response = get_response(request)
  File "/home/small-spider/.virtualenvs/Working/lib/python3.6/site-packages/django/core/handlers/base.py", line 187, in _get_response
    response = self.process_exception_by_middleware(e, request)
  File "/home/small-spider/.virtualenvs/Working/lib/python3.6/site-packages/django/core/handlers/base.py", line 185, in _get_response
    response = wrapped_callback(request, *callback_args, **callback_kwargs)
  File "/home/small-spider/.virtualenvs/Working/lib/python3.6/site-packages/django/views/generic/base.py", line 68, in view
    return self.dispatch(request, *args, **kwargs)
  File "/home/small-spider/.virtualenvs/Working/lib/python3.6/site-packages/django/views/generic/base.py", line 88, in dispatch
    return handler(request, *args, **kwargs)
  File "/home/small-spider/Documents/项目文件/线上版本/EPGN_INFO_4.17/apps/calculate/views.py", line 71, in post
    file_name = data["file_name"]
TypeError: string indices must be integers
ERROR 2020-06-03 10:49:45,250 exception 135 Internal Server Error: /channelList/
Traceback (most recent call last):
  File "/home/small-spider/.virtualenvs/Working/lib/python3.6/site-packages/django/core/handlers/exception.py", line 41, in inner
    response = get_response(request)
  File "/home/small-spider/.virtualenvs/Working/lib/python3.6/site-packages/django/core/handlers/base.py", line 187, in _get_response
    response = self.process_exception_by_middleware(e, request)
  File "/home/small-spider/.virtualenvs/Working/lib/python3.6/site-packages/django/core/handlers/base.py", line 185, in _get_response
    response = wrapped_callback(request, *callback_args, **callback_kwargs)
  File "/home/small-spider/.virtualenvs/Working/lib/python3.6/site-packages/django/views/generic/base.py", line 68, in view
    return self.dispatch(request, *args, **kwargs)
  File "/home/small-spider/.virtualenvs/Working/lib/python3.6/site-packages/django/views/generic/base.py", line 88, in dispatch
    return handler(request, *args, **kwargs)
  File "/home/small-spider/Documents/项目文件/线上版本/EPGN_INFO_4.17/apps/calculate/views.py", line 73, in post
    file_name = data["file_name"]
TypeError: string indices must be integers
ERROR 2020-06-03 10:49:45,812 exception 135 Internal Server Error: /user_calculate/
Traceback (most recent call last):
  File "/home/small-spider/.virtualenvs/Working/lib/python3.6/site-packages/django/core/handlers/exception.py", line 41, in inner
    response = get_response(request)
  File "/home/small-spider/.virtualenvs/Working/lib/python3.6/site-packages/django/core/handlers/base.py", line 187, in _get_response
    response = self.process_exception_by_middleware(e, request)
  File "/home/small-spider/.virtualenvs/Working/lib/python3.6/site-packages/django/core/handlers/base.py", line 185, in _get_response
    response = wrapped_callback(request, *callback_args, **callback_kwargs)
  File "/home/small-spider/Documents/项目文件/线上版本/EPGN_INFO_4.17/apps/calculate/views.py", line 383, in manual_report
    items = ParseTask(data, rpm_type).run()
  File "./scripts/process_gecent.py", line 91, in run
    self.parse_file_info()
  File "./scripts/process_gecent.py", line 48, in parse_file_info
    channel_data_key = list(channel_file_list.keys())[list(channel_file_list.values()).index(channel["title"])]
ValueError: 'data_hintenrechts' is not in list
ERROR 2020-06-03 10:51:10,759 exception 135 Internal Server Error: /channelList/
Traceback (most recent call last):
  File "/home/small-spider/.virtualenvs/Working/lib/python3.6/site-packages/django/core/handlers/exception.py", line 41, in inner
    response = get_response(request)
  File "/home/small-spider/.virtualenvs/Working/lib/python3.6/site-packages/django/core/handlers/base.py", line 187, in _get_response
    response = self.process_exception_by_middleware(e, request)
  File "/home/small-spider/.virtualenvs/Working/lib/python3.6/site-packages/django/core/handlers/base.py", line 185, in _get_response
    response = wrapped_callback(request, *callback_args, **callback_kwargs)
  File "/home/small-spider/.virtualenvs/Working/lib/python3.6/site-packages/django/views/generic/base.py", line 68, in view
    return self.dispatch(request, *args, **kwargs)
  File "/home/small-spider/.virtualenvs/Working/lib/python3.6/site-packages/django/views/generic/base.py", line 88, in dispatch
    return handler(request, *args, **kwargs)
  File "/home/small-spider/Documents/项目文件/线上版本/EPGN_INFO_4.17/apps/calculate/views.py", line 33, in put
    channel_dict, items = read_hdf(file_name)
  File "./scripts/readHDF.py", line 12, in read_hdf
    read_info = h5py.File(file_path, 'r')
  File "/home/small-spider/.virtualenvs/Working/lib/python3.6/site-packages/h5py/_hl/files.py", line 408, in __init__
    swmr=swmr)
  File "/home/small-spider/.virtualenvs/Working/lib/python3.6/site-packages/h5py/_hl/files.py", line 173, in make_fid
    fid = h5f.open(name, flags, fapl=fapl)
  File "h5py/_objects.pyx", line 54, in h5py._objects.with_phil.wrapper
  File "h5py/_objects.pyx", line 55, in h5py._objects.with_phil.wrapper
  File "h5py/h5f.pyx", line 88, in h5py.h5f.open
OSError: Unable to open file (unable to open file: name = '/media/sf_Y_DRIVE/Database/R_HDF/2020-05-18_BMK 80kmph run01.hdf', errno = 2, error message = 'No such file or directory', flags = 0, o_flags = 0)
ERROR 2020-06-03 10:53:56,407 exception 135 Internal Server Error: /channelList/
Traceback (most recent call last):
  File "/home/small-spider/.virtualenvs/Working/lib/python3.6/site-packages/django/core/handlers/exception.py", line 41, in inner
    response = get_response(request)
  File "/home/small-spider/.virtualenvs/Working/lib/python3.6/site-packages/django/core/handlers/base.py", line 187, in _get_response
    response = self.process_exception_by_middleware(e, request)
  File "/home/small-spider/.virtualenvs/Working/lib/python3.6/site-packages/django/core/handlers/base.py", line 185, in _get_response
    response = wrapped_callback(request, *callback_args, **callback_kwargs)
  File "/home/small-spider/.virtualenvs/Working/lib/python3.6/site-packages/django/views/generic/base.py", line 68, in view
    return self.dispatch(request, *args, **kwargs)
  File "/home/small-spider/.virtualenvs/Working/lib/python3.6/site-packages/django/views/generic/base.py", line 88, in dispatch
    return handler(request, *args, **kwargs)
  File "/home/small-spider/Documents/项目文件/线上版本/EPGN_INFO_4.17/apps/calculate/views.py", line 73, in post
    file_name = data["file_name"]
TypeError: string indices must be integers
ERROR 2020-06-03 10:54:16,766 exception 135 Internal Server Error: /channelList/
Traceback (most recent call last):
  File "/home/small-spider/.virtualenvs/Working/lib/python3.6/site-packages/django/core/handlers/exception.py", line 41, in inner
    response = get_response(request)
  File "/home/small-spider/.virtualenvs/Working/lib/python3.6/site-packages/django/core/handlers/base.py", line 187, in _get_response
    response = self.process_exception_by_middleware(e, request)
  File "/home/small-spider/.virtualenvs/Working/lib/python3.6/site-packages/django/core/handlers/base.py", line 185, in _get_response
    response = wrapped_callback(request, *callback_args, **callback_kwargs)
  File "/home/small-spider/.virtualenvs/Working/lib/python3.6/site-packages/django/views/generic/base.py", line 68, in view
    return self.dispatch(request, *args, **kwargs)
  File "/home/small-spider/.virtualenvs/Working/lib/python3.6/site-packages/django/views/generic/base.py", line 88, in dispatch
    return handler(request, *args, **kwargs)
  File "/home/small-spider/Documents/项目文件/线上版本/EPGN_INFO_4.17/apps/calculate/views.py", line 73, in post
    file_name = data["file_name"]
TypeError: string indices must be integers
ERROR 2020-06-03 10:54:58,553 exception 135 Internal Server Error: /channelList/
Traceback (most recent call last):
  File "/home/small-spider/.virtualenvs/Working/lib/python3.6/site-packages/django/core/handlers/exception.py", line 41, in inner
    response = get_response(request)
  File "/home/small-spider/.virtualenvs/Working/lib/python3.6/site-packages/django/core/handlers/base.py", line 187, in _get_response
    response = self.process_exception_by_middleware(e, request)
  File "/home/small-spider/.virtualenvs/Working/lib/python3.6/site-packages/django/core/handlers/base.py", line 185, in _get_response
    response = wrapped_callback(request, *callback_args, **callback_kwargs)
  File "/home/small-spider/.virtualenvs/Working/lib/python3.6/site-packages/django/views/generic/base.py", line 68, in view
    return self.dispatch(request, *args, **kwargs)
  File "/home/small-spider/.virtualenvs/Working/lib/python3.6/site-packages/django/views/generic/base.py", line 88, in dispatch
    return handler(request, *args, **kwargs)
  File "/home/small-spider/Documents/项目文件/线上版本/EPGN_INFO_4.17/apps/calculate/views.py", line 73, in post
    file_name = data["file_name"]
TypeError: string indices must be integers
ERROR 2020-06-03 10:56:01,554 exception 135 Internal Server Error: /channelList/
Traceback (most recent call last):
  File "/home/small-spider/.virtualenvs/Working/lib/python3.6/site-packages/django/core/handlers/exception.py", line 41, in inner
    response = get_response(request)
  File "/home/small-spider/.virtualenvs/Working/lib/python3.6/site-packages/django/core/handlers/base.py", line 187, in _get_response
    response = self.process_exception_by_middleware(e, request)
  File "/home/small-spider/.virtualenvs/Working/lib/python3.6/site-packages/django/core/handlers/base.py", line 185, in _get_response
    response = wrapped_callback(request, *callback_args, **callback_kwargs)
  File "/home/small-spider/.virtualenvs/Working/lib/python3.6/site-packages/django/views/generic/base.py", line 68, in view
    return self.dispatch(request, *args, **kwargs)
  File "/home/small-spider/.virtualenvs/Working/lib/python3.6/site-packages/django/views/generic/base.py", line 88, in dispatch
    return handler(request, *args, **kwargs)
  File "/home/small-spider/Documents/项目文件/线上版本/EPGN_INFO_4.17/apps/calculate/views.py", line 73, in post
    file_name = data["file_name"]
TypeError: string indices must be integers
ERROR 2020-06-03 10:59:16,880 exception 135 Internal Server Error: /channelList/
Traceback (most recent call last):
  File "/home/small-spider/.virtualenvs/Working/lib/python3.6/site-packages/django/core/handlers/exception.py", line 41, in inner
    response = get_response(request)
  File "/home/small-spider/.virtualenvs/Working/lib/python3.6/site-packages/django/core/handlers/base.py", line 187, in _get_response
    response = self.process_exception_by_middleware(e, request)
  File "/home/small-spider/.virtualenvs/Working/lib/python3.6/site-packages/django/core/handlers/base.py", line 185, in _get_response
    response = wrapped_callback(request, *callback_args, **callback_kwargs)
  File "/home/small-spider/.virtualenvs/Working/lib/python3.6/site-packages/django/views/generic/base.py", line 68, in view
    return self.dispatch(request, *args, **kwargs)
  File "/home/small-spider/.virtualenvs/Working/lib/python3.6/site-packages/django/views/generic/base.py", line 88, in dispatch
    return handler(request, *args, **kwargs)
  File "/home/small-spider/Documents/项目文件/线上版本/EPGN_INFO_4.17/apps/calculate/views.py", line 73, in post
    file_name = data["file_name"]
TypeError: string indices must be integers
ERROR 2020-06-03 11:01:34,324 exception 135 Internal Server Error: /channelList/
Traceback (most recent call last):
  File "/home/small-spider/.virtualenvs/Working/lib/python3.6/site-packages/django/core/handlers/exception.py", line 41, in inner
    response = get_response(request)
  File "/home/small-spider/.virtualenvs/Working/lib/python3.6/site-packages/django/core/handlers/base.py", line 187, in _get_response
    response = self.process_exception_by_middleware(e, request)
  File "/home/small-spider/.virtualenvs/Working/lib/python3.6/site-packages/django/core/handlers/base.py", line 185, in _get_response
    response = wrapped_callback(request, *callback_args, **callback_kwargs)
  File "/home/small-spider/.virtualenvs/Working/lib/python3.6/site-packages/django/views/generic/base.py", line 68, in view
    return self.dispatch(request, *args, **kwargs)
  File "/home/small-spider/.virtualenvs/Working/lib/python3.6/site-packages/django/views/generic/base.py", line 88, in dispatch
    return handler(request, *args, **kwargs)
  File "/home/small-spider/Documents/项目文件/线上版本/EPGN_INFO_4.17/apps/calculate/views.py", line 73, in post
    file_name = data["file_name"]
TypeError: string indices must be integers
ERROR 2020-06-03 11:24:33,182 exception 135 Internal Server Error: /channelList/
Traceback (most recent call last):
  File "/home/small-spider/.virtualenvs/Working/lib/python3.6/site-packages/django/core/handlers/exception.py", line 41, in inner
    response = get_response(request)
  File "/home/small-spider/.virtualenvs/Working/lib/python3.6/site-packages/django/core/handlers/base.py", line 187, in _get_response
    response = self.process_exception_by_middleware(e, request)
  File "/home/small-spider/.virtualenvs/Working/lib/python3.6/site-packages/django/core/handlers/base.py", line 185, in _get_response
    response = wrapped_callback(request, *callback_args, **callback_kwargs)
  File "/home/small-spider/.virtualenvs/Working/lib/python3.6/site-packages/django/views/generic/base.py", line 68, in view
    return self.dispatch(request, *args, **kwargs)
  File "/home/small-spider/.virtualenvs/Working/lib/python3.6/site-packages/django/views/generic/base.py", line 88, in dispatch
    return handler(request, *args, **kwargs)
  File "/home/small-spider/Documents/项目文件/线上版本/EPGN_INFO_4.17/apps/calculate/views.py", line 73, in post
    file_name = data["file_name"]
TypeError: string indices must be integers
ERROR 2020-06-03 11:27:07,886 exception 135 Internal Server Error: /channelList/
Traceback (most recent call last):
  File "/home/small-spider/.virtualenvs/Working/lib/python3.6/site-packages/django/core/handlers/exception.py", line 41, in inner
    response = get_response(request)
  File "/home/small-spider/.virtualenvs/Working/lib/python3.6/site-packages/django/core/handlers/base.py", line 187, in _get_response
    response = self.process_exception_by_middleware(e, request)
  File "/home/small-spider/.virtualenvs/Working/lib/python3.6/site-packages/django/core/handlers/base.py", line 185, in _get_response
    response = wrapped_callback(request, *callback_args, **callback_kwargs)
  File "/home/small-spider/.virtualenvs/Working/lib/python3.6/site-packages/django/views/generic/base.py", line 68, in view
    return self.dispatch(request, *args, **kwargs)
  File "/home/small-spider/.virtualenvs/Working/lib/python3.6/site-packages/django/views/generic/base.py", line 88, in dispatch
    return handler(request, *args, **kwargs)
  File "/home/small-spider/Documents/项目文件/线上版本/EPGN_INFO_4.17/apps/calculate/views.py", line 73, in post
    file_name = data["file_name"]
TypeError: string indices must be integers
ERROR 2020-06-03 12:23:57,670 exception 135 Internal Server Error: /channelList/
Traceback (most recent call last):
  File "/home/small-spider/.virtualenvs/Working/lib/python3.6/site-packages/django/core/handlers/exception.py", line 41, in inner
    response = get_response(request)
  File "/home/small-spider/.virtualenvs/Working/lib/python3.6/site-packages/django/core/handlers/base.py", line 187, in _get_response
    response = self.process_exception_by_middleware(e, request)
  File "/home/small-spider/.virtualenvs/Working/lib/python3.6/site-packages/django/core/handlers/base.py", line 185, in _get_response
    response = wrapped_callback(request, *callback_args, **callback_kwargs)
  File "/home/small-spider/.virtualenvs/Working/lib/python3.6/site-packages/django/views/generic/base.py", line 68, in view
    return self.dispatch(request, *args, **kwargs)
  File "/home/small-spider/.virtualenvs/Working/lib/python3.6/site-packages/django/views/generic/base.py", line 88, in dispatch
    return handler(request, *args, **kwargs)
  File "/home/small-spider/Documents/项目文件/线上版本/EPGN_INFO_4.17/apps/calculate/views.py", line 73, in post
    file_name = data["file_name"]
TypeError: string indices must be integers
ERROR 2020-06-03 12:26:13,098 exception 135 Internal Server Error: /channelList/
Traceback (most recent call last):
  File "/home/small-spider/.virtualenvs/Working/lib/python3.6/site-packages/django/core/handlers/exception.py", line 41, in inner
    response = get_response(request)
  File "/home/small-spider/.virtualenvs/Working/lib/python3.6/site-packages/django/core/handlers/base.py", line 187, in _get_response
    response = self.process_exception_by_middleware(e, request)
  File "/home/small-spider/.virtualenvs/Working/lib/python3.6/site-packages/django/core/handlers/base.py", line 185, in _get_response
    response = wrapped_callback(request, *callback_args, **callback_kwargs)
  File "/home/small-spider/.virtualenvs/Working/lib/python3.6/site-packages/django/views/generic/base.py", line 68, in view
    return self.dispatch(request, *args, **kwargs)
  File "/home/small-spider/.virtualenvs/Working/lib/python3.6/site-packages/django/views/generic/base.py", line 88, in dispatch
    return handler(request, *args, **kwargs)
  File "/home/small-spider/Documents/项目文件/线上版本/EPGN_INFO_4.17/apps/calculate/views.py", line 73, in post
    file_name = data["file_name"]
TypeError: string indices must be integers
ERROR 2020-06-03 12:26:13,116 exception 135 Internal Server Error: /user_calculate/
Traceback (most recent call last):
  File "/home/small-spider/.virtualenvs/Working/lib/python3.6/site-packages/django/core/handlers/exception.py", line 41, in inner
    response = get_response(request)
  File "/home/small-spider/.virtualenvs/Working/lib/python3.6/site-packages/django/core/handlers/base.py", line 187, in _get_response
    response = self.process_exception_by_middleware(e, request)
  File "/home/small-spider/.virtualenvs/Working/lib/python3.6/site-packages/django/core/handlers/base.py", line 185, in _get_response
    response = wrapped_callback(request, *callback_args, **callback_kwargs)
  File "/home/small-spider/Documents/项目文件/线上版本/EPGN_INFO_4.17/apps/calculate/views.py", line 366, in manual_report
    "calculate": CalculateNameDict[body_json["calculate_name"]],
KeyError: 'FFT对时间'
ERROR 2020-06-03 12:26:17,881 exception 135 Internal Server Error: /channelList/
Traceback (most recent call last):
  File "/home/small-spider/.virtualenvs/Working/lib/python3.6/site-packages/django/core/handlers/exception.py", line 41, in inner
    response = get_response(request)
  File "/home/small-spider/.virtualenvs/Working/lib/python3.6/site-packages/django/core/handlers/base.py", line 187, in _get_response
    response = self.process_exception_by_middleware(e, request)
  File "/home/small-spider/.virtualenvs/Working/lib/python3.6/site-packages/django/core/handlers/base.py", line 185, in _get_response
    response = wrapped_callback(request, *callback_args, **callback_kwargs)
  File "/home/small-spider/.virtualenvs/Working/lib/python3.6/site-packages/django/views/generic/base.py", line 68, in view
    return self.dispatch(request, *args, **kwargs)
  File "/home/small-spider/.virtualenvs/Working/lib/python3.6/site-packages/django/views/generic/base.py", line 88, in dispatch
    return handler(request, *args, **kwargs)
  File "/home/small-spider/Documents/项目文件/线上版本/EPGN_INFO_4.17/apps/calculate/views.py", line 73, in post
    file_name = data["file_name"]
TypeError: string indices must be integers
ERROR 2020-06-03 12:26:17,899 exception 135 Internal Server Error: /user_calculate/
Traceback (most recent call last):
  File "/home/small-spider/.virtualenvs/Working/lib/python3.6/site-packages/django/core/handlers/exception.py", line 41, in inner
    response = get_response(request)
  File "/home/small-spider/.virtualenvs/Working/lib/python3.6/site-packages/django/core/handlers/base.py", line 187, in _get_response
    response = self.process_exception_by_middleware(e, request)
  File "/home/small-spider/.virtualenvs/Working/lib/python3.6/site-packages/django/core/handlers/base.py", line 185, in _get_response
    response = wrapped_callback(request, *callback_args, **callback_kwargs)
  File "/home/small-spider/Documents/项目文件/线上版本/EPGN_INFO_4.17/apps/calculate/views.py", line 366, in manual_report
    "calculate": CalculateNameDict[body_json["calculate_name"]],
KeyError: 'FFT对时间'
ERROR 2020-06-03 12:28:10,907 exception 135 Internal Server Error: /channelList/
Traceback (most recent call last):
  File "/home/small-spider/.virtualenvs/Working/lib/python3.6/site-packages/django/core/handlers/exception.py", line 41, in inner
    response = get_response(request)
  File "/home/small-spider/.virtualenvs/Working/lib/python3.6/site-packages/django/core/handlers/base.py", line 187, in _get_response
    response = self.process_exception_by_middleware(e, request)
  File "/home/small-spider/.virtualenvs/Working/lib/python3.6/site-packages/django/core/handlers/base.py", line 185, in _get_response
    response = wrapped_callback(request, *callback_args, **callback_kwargs)
  File "/home/small-spider/.virtualenvs/Working/lib/python3.6/site-packages/django/views/generic/base.py", line 68, in view
    return self.dispatch(request, *args, **kwargs)
  File "/home/small-spider/.virtualenvs/Working/lib/python3.6/site-packages/django/views/generic/base.py", line 88, in dispatch
    return handler(request, *args, **kwargs)
  File "/home/small-spider/Documents/项目文件/线上版本/EPGN_INFO_4.17/apps/calculate/views.py", line 73, in post
    file_name = data["file_name"]
TypeError: string indices must be integers
ERROR 2020-06-03 12:28:10,935 exception 135 Internal Server Error: /user_calculate/
Traceback (most recent call last):
  File "/home/small-spider/.virtualenvs/Working/lib/python3.6/site-packages/django/core/handlers/exception.py", line 41, in inner
    response = get_response(request)
  File "/home/small-spider/.virtualenvs/Working/lib/python3.6/site-packages/django/core/handlers/base.py", line 187, in _get_response
    response = self.process_exception_by_middleware(e, request)
  File "/home/small-spider/.virtualenvs/Working/lib/python3.6/site-packages/django/core/handlers/base.py", line 185, in _get_response
    response = wrapped_callback(request, *callback_args, **callback_kwargs)
  File "/home/small-spider/Documents/项目文件/线上版本/EPGN_INFO_4.17/apps/calculate/views.py", line 366, in manual_report
    "calculate": CalculateNameDict[body_json["calculate_name"]],
KeyError: 'FFT vs Time'
ERROR 2020-06-03 12:28:55,639 exception 135 Internal Server Error: /channelList/
Traceback (most recent call last):
  File "/home/small-spider/.virtualenvs/Working/lib/python3.6/site-packages/django/core/handlers/exception.py", line 41, in inner
    response = get_response(request)
  File "/home/small-spider/.virtualenvs/Working/lib/python3.6/site-packages/django/core/handlers/base.py", line 187, in _get_response
    response = self.process_exception_by_middleware(e, request)
  File "/home/small-spider/.virtualenvs/Working/lib/python3.6/site-packages/django/core/handlers/base.py", line 185, in _get_response
    response = wrapped_callback(request, *callback_args, **callback_kwargs)
  File "/home/small-spider/.virtualenvs/Working/lib/python3.6/site-packages/django/views/generic/base.py", line 68, in view
    return self.dispatch(request, *args, **kwargs)
  File "/home/small-spider/.virtualenvs/Working/lib/python3.6/site-packages/django/views/generic/base.py", line 88, in dispatch
    return handler(request, *args, **kwargs)
  File "/home/small-spider/Documents/项目文件/线上版本/EPGN_INFO_4.17/apps/calculate/views.py", line 73, in post
    file_name = data["file_name"]
TypeError: string indices must be integers
ERROR 2020-06-03 12:31:38,402 exception 135 Internal Server Error: /channelList/
Traceback (most recent call last):
  File "/home/small-spider/.virtualenvs/Working/lib/python3.6/site-packages/django/core/handlers/exception.py", line 41, in inner
    response = get_response(request)
  File "/home/small-spider/.virtualenvs/Working/lib/python3.6/site-packages/django/core/handlers/base.py", line 187, in _get_response
    response = self.process_exception_by_middleware(e, request)
  File "/home/small-spider/.virtualenvs/Working/lib/python3.6/site-packages/django/core/handlers/base.py", line 185, in _get_response
    response = wrapped_callback(request, *callback_args, **callback_kwargs)
  File "/home/small-spider/.virtualenvs/Working/lib/python3.6/site-packages/django/views/generic/base.py", line 68, in view
    return self.dispatch(request, *args, **kwargs)
  File "/home/small-spider/.virtualenvs/Working/lib/python3.6/site-packages/django/views/generic/base.py", line 88, in dispatch
    return handler(request, *args, **kwargs)
  File "/home/small-spider/Documents/项目文件/线上版本/EPGN_INFO_4.17/apps/calculate/views.py", line 73, in post
    file_name = data["file_name"]
TypeError: string indices must be integers
ERROR 2020-06-03 14:19:39,676 exception 135 Internal Server Error: /channelList/
Traceback (most recent call last):
  File "/home/small-spider/.virtualenvs/Working/lib/python3.6/site-packages/django/core/handlers/exception.py", line 41, in inner
    response = get_response(request)
  File "/home/small-spider/.virtualenvs/Working/lib/python3.6/site-packages/django/core/handlers/base.py", line 187, in _get_response
    response = self.process_exception_by_middleware(e, request)
  File "/home/small-spider/.virtualenvs/Working/lib/python3.6/site-packages/django/core/handlers/base.py", line 185, in _get_response
    response = wrapped_callback(request, *callback_args, **callback_kwargs)
  File "/home/small-spider/.virtualenvs/Working/lib/python3.6/site-packages/django/views/generic/base.py", line 68, in view
    return self.dispatch(request, *args, **kwargs)
  File "/home/small-spider/.virtualenvs/Working/lib/python3.6/site-packages/django/views/generic/base.py", line 88, in dispatch
    return handler(request, *args, **kwargs)
  File "/home/small-spider/Documents/项目文件/线上版本/EPGN_INFO_4.17/apps/calculate/views.py", line 33, in put
    channel_dict, items = read_hdf(file_name)
  File "./scripts/readHDF.py", line 12, in read_hdf
    read_info = h5py.File(file_path, 'r')
  File "/home/small-spider/.virtualenvs/Working/lib/python3.6/site-packages/h5py/_hl/files.py", line 408, in __init__
    swmr=swmr)
  File "/home/small-spider/.virtualenvs/Working/lib/python3.6/site-packages/h5py/_hl/files.py", line 173, in make_fid
    fid = h5f.open(name, flags, fapl=fapl)
  File "h5py/_objects.pyx", line 54, in h5py._objects.with_phil.wrapper
  File "h5py/_objects.pyx", line 55, in h5py._objects.with_phil.wrapper
  File "h5py/h5f.pyx", line 88, in h5py.h5f.open
OSError: Unable to open file (unable to open file: name = '/media/sf_Y_DRIVE/Database/R_HDF/2020-06-03_TEST_A9I-428 KP 80-20kmph run04_CAN.hdf', errno = 2, error message = 'No such file or directory', flags = 0, o_flags = 0)
ERROR 2020-06-03 14:30:33,265 exception 135 Internal Server Error: /channelList/
Traceback (most recent call last):
  File "/home/small-spider/.virtualenvs/Working/lib/python3.6/site-packages/django/core/handlers/exception.py", line 41, in inner
    response = get_response(request)
  File "/home/small-spider/.virtualenvs/Working/lib/python3.6/site-packages/django/core/handlers/base.py", line 187, in _get_response
    response = self.process_exception_by_middleware(e, request)
  File "/home/small-spider/.virtualenvs/Working/lib/python3.6/site-packages/django/core/handlers/base.py", line 185, in _get_response
    response = wrapped_callback(request, *callback_args, **callback_kwargs)
  File "/home/small-spider/.virtualenvs/Working/lib/python3.6/site-packages/django/views/generic/base.py", line 68, in view
    return self.dispatch(request, *args, **kwargs)
  File "/home/small-spider/.virtualenvs/Working/lib/python3.6/site-packages/django/views/generic/base.py", line 88, in dispatch
    return handler(request, *args, **kwargs)
  File "/home/small-spider/Documents/项目文件/线上版本/EPGN_INFO_4.17/apps/calculate/views.py", line 73, in post
    file_name = data["file_name"]
TypeError: string indices must be integers
ERROR 2020-06-03 14:33:03,222 exception 135 Internal Server Error: /channelList/
Traceback (most recent call last):
  File "/home/small-spider/.virtualenvs/Working/lib/python3.6/site-packages/django/core/handlers/exception.py", line 41, in inner
    response = get_response(request)
  File "/home/small-spider/.virtualenvs/Working/lib/python3.6/site-packages/django/core/handlers/base.py", line 187, in _get_response
    response = self.process_exception_by_middleware(e, request)
  File "/home/small-spider/.virtualenvs/Working/lib/python3.6/site-packages/django/core/handlers/base.py", line 185, in _get_response
    response = wrapped_callback(request, *callback_args, **callback_kwargs)
  File "/home/small-spider/.virtualenvs/Working/lib/python3.6/site-packages/django/views/generic/base.py", line 68, in view
    return self.dispatch(request, *args, **kwargs)
  File "/home/small-spider/.virtualenvs/Working/lib/python3.6/site-packages/django/views/generic/base.py", line 88, in dispatch
    return handler(request, *args, **kwargs)
  File "/home/small-spider/Documents/项目文件/线上版本/EPGN_INFO_4.17/apps/calculate/views.py", line 33, in put
    channel_dict, items = read_hdf(file_name)
  File "./scripts/readHDF.py", line 12, in read_hdf
    read_info = h5py.File(file_path, 'r')
  File "/home/small-spider/.virtualenvs/Working/lib/python3.6/site-packages/h5py/_hl/files.py", line 408, in __init__
    swmr=swmr)
  File "/home/small-spider/.virtualenvs/Working/lib/python3.6/site-packages/h5py/_hl/files.py", line 173, in make_fid
    fid = h5f.open(name, flags, fapl=fapl)
  File "h5py/_objects.pyx", line 54, in h5py._objects.with_phil.wrapper
  File "h5py/_objects.pyx", line 55, in h5py._objects.with_phil.wrapper
  File "h5py/h5f.pyx", line 88, in h5py.h5f.open
OSError: Unable to open file (unable to open file: name = '/media/sf_Y_DRIVE/Database/R_HDF/2020-06-03_TEST_A9I-428 KP 80-20kmph run04_CAN.hdf', errno = 2, error message = 'No such file or directory', flags = 0, o_flags = 0)
ERROR 2020-06-03 14:33:09,359 exception 135 Internal Server Error: /channelList/
Traceback (most recent call last):
  File "/home/small-spider/.virtualenvs/Working/lib/python3.6/site-packages/django/core/handlers/exception.py", line 41, in inner
    response = get_response(request)
  File "/home/small-spider/.virtualenvs/Working/lib/python3.6/site-packages/django/core/handlers/base.py", line 187, in _get_response
    response = self.process_exception_by_middleware(e, request)
  File "/home/small-spider/.virtualenvs/Working/lib/python3.6/site-packages/django/core/handlers/base.py", line 185, in _get_response
    response = wrapped_callback(request, *callback_args, **callback_kwargs)
  File "/home/small-spider/.virtualenvs/Working/lib/python3.6/site-packages/django/views/generic/base.py", line 68, in view
    return self.dispatch(request, *args, **kwargs)
  File "/home/small-spider/.virtualenvs/Working/lib/python3.6/site-packages/django/views/generic/base.py", line 88, in dispatch
    return handler(request, *args, **kwargs)
  File "/home/small-spider/Documents/项目文件/线上版本/EPGN_INFO_4.17/apps/calculate/views.py", line 33, in put
    channel_dict, items = read_hdf(file_name)
  File "./scripts/readHDF.py", line 12, in read_hdf
    read_info = h5py.File(file_path, 'r')
  File "/home/small-spider/.virtualenvs/Working/lib/python3.6/site-packages/h5py/_hl/files.py", line 408, in __init__
    swmr=swmr)
  File "/home/small-spider/.virtualenvs/Working/lib/python3.6/site-packages/h5py/_hl/files.py", line 173, in make_fid
    fid = h5f.open(name, flags, fapl=fapl)
  File "h5py/_objects.pyx", line 54, in h5py._objects.with_phil.wrapper
  File "h5py/_objects.pyx", line 55, in h5py._objects.with_phil.wrapper
  File "h5py/h5f.pyx", line 88, in h5py.h5f.open
OSError: Unable to open file (unable to open file: name = '/media/sf_Y_DRIVE/Database/R_HDF/2020-06-03_TEST_A9I-428 KP 80-20kmph run04_CAN.hdf', errno = 2, error message = 'No such file or directory', flags = 0, o_flags = 0)
ERROR 2020-06-03 14:49:23,995 exception 135 Internal Server Error: /channelList/
Traceback (most recent call last):
  File "/home/small-spider/.virtualenvs/Working/lib/python3.6/site-packages/django/core/handlers/exception.py", line 41, in inner
    response = get_response(request)
  File "/home/small-spider/.virtualenvs/Working/lib/python3.6/site-packages/django/core/handlers/base.py", line 187, in _get_response
    response = self.process_exception_by_middleware(e, request)
  File "/home/small-spider/.virtualenvs/Working/lib/python3.6/site-packages/django/core/handlers/base.py", line 185, in _get_response
    response = wrapped_callback(request, *callback_args, **callback_kwargs)
  File "/home/small-spider/.virtualenvs/Working/lib/python3.6/site-packages/django/views/generic/base.py", line 68, in view
    return self.dispatch(request, *args, **kwargs)
  File "/home/small-spider/.virtualenvs/Working/lib/python3.6/site-packages/django/views/generic/base.py", line 88, in dispatch
    return handler(request, *args, **kwargs)
  File "/home/small-spider/Documents/项目文件/线上版本/EPGN_INFO_4.17/apps/calculate/views.py", line 33, in put
    channel_dict, items = read_hdf(file_name)
  File "./scripts/readHDF.py", line 12, in read_hdf
    read_info = h5py.File(file_path, 'r')
  File "/home/small-spider/.virtualenvs/Working/lib/python3.6/site-packages/h5py/_hl/files.py", line 408, in __init__
    swmr=swmr)
  File "/home/small-spider/.virtualenvs/Working/lib/python3.6/site-packages/h5py/_hl/files.py", line 173, in make_fid
    fid = h5f.open(name, flags, fapl=fapl)
  File "h5py/_objects.pyx", line 54, in h5py._objects.with_phil.wrapper
  File "h5py/_objects.pyx", line 55, in h5py._objects.with_phil.wrapper
  File "h5py/h5f.pyx", line 88, in h5py.h5f.open
OSError: Unable to open file (unable to open file: name = '/media/sf_Y_DRIVE/Database/R_HDF/2020-06-03_TEST_A9I-428 KP 80-20kmph run04_CAN.hdf', errno = 2, error message = 'No such file or directory', flags = 0, o_flags = 0)
ERROR 2020-06-03 14:49:51,270 exception 135 Internal Server Error: /channelList/
Traceback (most recent call last):
  File "/home/small-spider/.virtualenvs/Working/lib/python3.6/site-packages/django/core/handlers/exception.py", line 41, in inner
    response = get_response(request)
  File "/home/small-spider/.virtualenvs/Working/lib/python3.6/site-packages/django/core/handlers/base.py", line 187, in _get_response
    response = self.process_exception_by_middleware(e, request)
  File "/home/small-spider/.virtualenvs/Working/lib/python3.6/site-packages/django/core/handlers/base.py", line 185, in _get_response
    response = wrapped_callback(request, *callback_args, **callback_kwargs)
  File "/home/small-spider/.virtualenvs/Working/lib/python3.6/site-packages/django/views/generic/base.py", line 68, in view
    return self.dispatch(request, *args, **kwargs)
  File "/home/small-spider/.virtualenvs/Working/lib/python3.6/site-packages/django/views/generic/base.py", line 88, in dispatch
    return handler(request, *args, **kwargs)
  File "/home/small-spider/Documents/项目文件/线上版本/EPGN_INFO_4.17/apps/calculate/views.py", line 73, in post
    file_name = data["file_name"]
TypeError: string indices must be integers
WARNING 2020-06-03 14:57:45,825 base 152 Not Found: /complainUpload/
WARNING 2020-06-04 10:10:42,122 base 152 Not Found: /epgn_front_end/upload.html
